2024-11-18 07:29:43 [INFO] django.utils.autoreload (autoreload): Watching for file changes with StatReloader
2024-11-18 07:32:45 [INFO] django.utils.autoreload (autoreload): Watching for file changes with StatReloader
2024-11-18 07:33:10 [INFO] django.utils.autoreload (autoreload): Watching for file changes with StatReloader
2024-11-18 07:33:45 [INFO] django.utils.autoreload (autoreload): Watching for file changes with StatReloader
2024-11-18 07:33:45 [DEBUG] faiss.loader (loader): Environment variable FAISS_OPT_LEVEL is not set, so let's pick the instruction set according to the current CPU
2024-11-18 07:33:45 [INFO] faiss.loader (loader): Loading faiss with AVX2 support.
2024-11-18 07:33:45 [INFO] faiss.loader (loader): Successfully loaded faiss with AVX2 support.
2024-11-18 07:40:29 [INFO] django.utils.autoreload (autoreload): Watching for file changes with StatReloader
2024-11-18 07:40:29 [DEBUG] faiss.loader (loader): Environment variable FAISS_OPT_LEVEL is not set, so let's pick the instruction set according to the current CPU
2024-11-18 07:40:29 [INFO] faiss.loader (loader): Loading faiss with AVX2 support.
2024-11-18 07:40:30 [INFO] faiss.loader (loader): Successfully loaded faiss with AVX2 support.
2024-11-18 07:41:00 [INFO] django.utils.autoreload (autoreload): Watching for file changes with StatReloader
2024-11-18 07:41:00 [DEBUG] faiss.loader (loader): Environment variable FAISS_OPT_LEVEL is not set, so let's pick the instruction set according to the current CPU
2024-11-18 07:41:00 [INFO] faiss.loader (loader): Loading faiss with AVX2 support.
2024-11-18 07:41:00 [INFO] faiss.loader (loader): Successfully loaded faiss with AVX2 support.
2024-11-18 07:41:07 [INFO] api.views (views): Fetching all festivals.
2024-11-18 07:43:02 [WARNING] django.request (log): Not Found: /
2024-11-18 07:43:05 [WARNING] django.request (log): Not Found: /
2024-11-18 07:43:07 [INFO] api.views (views): Fetching all comments.
2024-11-18 07:43:07 [INFO] api.views (views): Fetching all comments.
2024-11-18 07:43:15 [INFO] api.views (views): Fetching all comments.
2024-11-18 07:43:15 [INFO] api.views (views): Fetching all comments.
2024-11-18 07:43:15 [WARNING] django.request (log): Not Found: /api
2024-11-18 07:43:22 [INFO] api.views (views): Fetching all comments.
2024-11-18 07:43:22 [INFO] api.views (views): Fetching all comments.
2024-11-18 07:43:23 [WARNING] django.request (log): Not Found: /api/
2024-11-18 07:43:35 [WARNING] django.request (log): Method Not Allowed: /api/restaurant_chatbot/
2024-11-18 07:45:18 [ERROR] django.request (log): Internal Server Error: /api/restaurant_chatbot/
2024-11-18 07:46:36 [INFO] sentence_transformers.SentenceTransformer (SentenceTransformer): Use pytorch device_name: cpu
2024-11-18 07:46:36 [INFO] sentence_transformers.SentenceTransformer (SentenceTransformer): Load pretrained SentenceTransformer: intfloat/multilingual-e5-large-instruct
2024-11-18 07:46:36 [DEBUG] urllib3.connectionpool (connectionpool): Starting new HTTPS connection (1): huggingface.co:443
2024-11-18 07:46:36 [DEBUG] urllib3.connectionpool (connectionpool): https://huggingface.co:443 "HEAD /intfloat/multilingual-e5-large-instruct/resolve/main/modules.json HTTP/11" 200 0
2024-11-18 07:46:36 [DEBUG] filelock (_api): Attempting to acquire lock 123389000464000 on /home/zxc/.cache/huggingface/hub/.locks/models--intfloat--multilingual-e5-large-instruct/952a9b81c0bfd99800fabf352f69c7ccd46c5e43.lock
2024-11-18 07:46:36 [DEBUG] filelock (_api): Lock 123389000464000 acquired on /home/zxc/.cache/huggingface/hub/.locks/models--intfloat--multilingual-e5-large-instruct/952a9b81c0bfd99800fabf352f69c7ccd46c5e43.lock
2024-11-18 07:46:37 [DEBUG] urllib3.connectionpool (connectionpool): https://huggingface.co:443 "GET /intfloat/multilingual-e5-large-instruct/resolve/main/modules.json HTTP/11" 200 349
2024-11-18 07:46:37 [DEBUG] filelock (_api): Attempting to release lock 123389000464000 on /home/zxc/.cache/huggingface/hub/.locks/models--intfloat--multilingual-e5-large-instruct/952a9b81c0bfd99800fabf352f69c7ccd46c5e43.lock
2024-11-18 07:46:37 [DEBUG] filelock (_api): Lock 123389000464000 released on /home/zxc/.cache/huggingface/hub/.locks/models--intfloat--multilingual-e5-large-instruct/952a9b81c0bfd99800fabf352f69c7ccd46c5e43.lock
2024-11-18 07:46:37 [DEBUG] urllib3.connectionpool (connectionpool): https://huggingface.co:443 "HEAD /intfloat/multilingual-e5-large-instruct/resolve/main/config_sentence_transformers.json HTTP/11" 200 0
2024-11-18 07:46:37 [DEBUG] filelock (_api): Attempting to acquire lock 123388995139632 on /home/zxc/.cache/huggingface/hub/.locks/models--intfloat--multilingual-e5-large-instruct/486b40b74e493da9295e67f851141d361e95b284.lock
2024-11-18 07:46:37 [DEBUG] filelock (_api): Lock 123388995139632 acquired on /home/zxc/.cache/huggingface/hub/.locks/models--intfloat--multilingual-e5-large-instruct/486b40b74e493da9295e67f851141d361e95b284.lock
2024-11-18 07:46:37 [DEBUG] urllib3.connectionpool (connectionpool): https://huggingface.co:443 "GET /intfloat/multilingual-e5-large-instruct/resolve/main/config_sentence_transformers.json HTTP/11" 200 128
2024-11-18 07:46:37 [DEBUG] filelock (_api): Attempting to release lock 123388995139632 on /home/zxc/.cache/huggingface/hub/.locks/models--intfloat--multilingual-e5-large-instruct/486b40b74e493da9295e67f851141d361e95b284.lock
2024-11-18 07:46:37 [DEBUG] filelock (_api): Lock 123388995139632 released on /home/zxc/.cache/huggingface/hub/.locks/models--intfloat--multilingual-e5-large-instruct/486b40b74e493da9295e67f851141d361e95b284.lock
2024-11-18 07:46:37 [DEBUG] urllib3.connectionpool (connectionpool): https://huggingface.co:443 "HEAD /intfloat/multilingual-e5-large-instruct/resolve/main/README.md HTTP/11" 200 0
2024-11-18 07:46:37 [DEBUG] filelock (_api): Attempting to acquire lock 123388994159296 on /home/zxc/.cache/huggingface/hub/.locks/models--intfloat--multilingual-e5-large-instruct/f89be7e54e86e2b0630c98f3d8410b7fd994bef8.lock
2024-11-18 07:46:37 [DEBUG] filelock (_api): Lock 123388994159296 acquired on /home/zxc/.cache/huggingface/hub/.locks/models--intfloat--multilingual-e5-large-instruct/f89be7e54e86e2b0630c98f3d8410b7fd994bef8.lock
2024-11-18 07:46:37 [DEBUG] urllib3.connectionpool (connectionpool): https://huggingface.co:443 "GET /intfloat/multilingual-e5-large-instruct/resolve/main/README.md HTTP/11" 200 139865
2024-11-18 07:46:37 [DEBUG] filelock (_api): Attempting to release lock 123388994159296 on /home/zxc/.cache/huggingface/hub/.locks/models--intfloat--multilingual-e5-large-instruct/f89be7e54e86e2b0630c98f3d8410b7fd994bef8.lock
2024-11-18 07:46:37 [DEBUG] filelock (_api): Lock 123388994159296 released on /home/zxc/.cache/huggingface/hub/.locks/models--intfloat--multilingual-e5-large-instruct/f89be7e54e86e2b0630c98f3d8410b7fd994bef8.lock
2024-11-18 07:46:38 [DEBUG] urllib3.connectionpool (connectionpool): https://huggingface.co:443 "HEAD /intfloat/multilingual-e5-large-instruct/resolve/main/modules.json HTTP/11" 200 0
2024-11-18 07:46:38 [DEBUG] urllib3.connectionpool (connectionpool): https://huggingface.co:443 "HEAD /intfloat/multilingual-e5-large-instruct/resolve/main/sentence_bert_config.json HTTP/11" 404 0
2024-11-18 07:46:38 [DEBUG] urllib3.connectionpool (connectionpool): https://huggingface.co:443 "HEAD /intfloat/multilingual-e5-large-instruct/resolve/main/sentence_roberta_config.json HTTP/11" 404 0
2024-11-18 07:46:38 [DEBUG] urllib3.connectionpool (connectionpool): https://huggingface.co:443 "HEAD /intfloat/multilingual-e5-large-instruct/resolve/main/sentence_distilbert_config.json HTTP/11" 404 0
2024-11-18 07:46:38 [DEBUG] urllib3.connectionpool (connectionpool): https://huggingface.co:443 "HEAD /intfloat/multilingual-e5-large-instruct/resolve/main/sentence_camembert_config.json HTTP/11" 404 0
2024-11-18 07:46:39 [DEBUG] urllib3.connectionpool (connectionpool): https://huggingface.co:443 "HEAD /intfloat/multilingual-e5-large-instruct/resolve/main/sentence_albert_config.json HTTP/11" 404 0
2024-11-18 07:46:39 [DEBUG] urllib3.connectionpool (connectionpool): https://huggingface.co:443 "HEAD /intfloat/multilingual-e5-large-instruct/resolve/main/sentence_xlm-roberta_config.json HTTP/11" 404 0
2024-11-18 07:46:39 [DEBUG] urllib3.connectionpool (connectionpool): https://huggingface.co:443 "HEAD /intfloat/multilingual-e5-large-instruct/resolve/main/sentence_xlnet_config.json HTTP/11" 404 0
2024-11-18 07:46:39 [DEBUG] urllib3.connectionpool (connectionpool): https://huggingface.co:443 "HEAD /intfloat/multilingual-e5-large-instruct/resolve/main/adapter_config.json HTTP/11" 404 0
2024-11-18 07:46:40 [DEBUG] urllib3.connectionpool (connectionpool): https://huggingface.co:443 "HEAD /intfloat/multilingual-e5-large-instruct/resolve/main/config.json HTTP/11" 200 0
2024-11-18 07:46:40 [DEBUG] filelock (_api): Attempting to acquire lock 123389021704304 on /home/zxc/.cache/huggingface/hub/.locks/models--intfloat--multilingual-e5-large-instruct/f92397ec9462da6e5e34fa22a43cf234093481e8.lock
2024-11-18 07:46:40 [DEBUG] filelock (_api): Lock 123389021704304 acquired on /home/zxc/.cache/huggingface/hub/.locks/models--intfloat--multilingual-e5-large-instruct/f92397ec9462da6e5e34fa22a43cf234093481e8.lock
2024-11-18 07:46:40 [DEBUG] urllib3.connectionpool (connectionpool): https://huggingface.co:443 "GET /intfloat/multilingual-e5-large-instruct/resolve/main/config.json HTTP/11" 200 690
2024-11-18 07:46:40 [DEBUG] filelock (_api): Attempting to release lock 123389021704304 on /home/zxc/.cache/huggingface/hub/.locks/models--intfloat--multilingual-e5-large-instruct/f92397ec9462da6e5e34fa22a43cf234093481e8.lock
2024-11-18 07:46:40 [DEBUG] filelock (_api): Lock 123389021704304 released on /home/zxc/.cache/huggingface/hub/.locks/models--intfloat--multilingual-e5-large-instruct/f92397ec9462da6e5e34fa22a43cf234093481e8.lock
2024-11-18 07:46:40 [DEBUG] urllib3.connectionpool (connectionpool): https://huggingface.co:443 "HEAD /intfloat/multilingual-e5-large-instruct/resolve/main/model.safetensors HTTP/11" 302 0
2024-11-18 07:46:40 [DEBUG] filelock (_api): Attempting to acquire lock 123388994670848 on /home/zxc/.cache/huggingface/hub/.locks/models--intfloat--multilingual-e5-large-instruct/dd6b6e4f52db0a7aff83a13d10e6c5342ef9f6ab799bad3221f4b35ef390fa85.lock
2024-11-18 07:46:40 [DEBUG] filelock (_api): Lock 123388994670848 acquired on /home/zxc/.cache/huggingface/hub/.locks/models--intfloat--multilingual-e5-large-instruct/dd6b6e4f52db0a7aff83a13d10e6c5342ef9f6ab799bad3221f4b35ef390fa85.lock
2024-11-18 07:46:40 [DEBUG] urllib3.connectionpool (connectionpool): Starting new HTTPS connection (1): cdn-lfs-us-1.hf.co:443
2024-11-18 07:46:40 [DEBUG] urllib3.connectionpool (connectionpool): https://cdn-lfs-us-1.hf.co:443 "GET /repos/13/22/13229d889872a27728134105f8349a8b23c84708fe519f55c2b08e858f21322a/dd6b6e4f52db0a7aff83a13d10e6c5342ef9f6ab799bad3221f4b35ef390fa85?response-content-disposition=inline%3B+filename*%3DUTF-8%27%27model.safetensors%3B+filename%3D%22model.safetensors%22%3B&Expires=1732175200&Policy=eyJTdGF0ZW1lbnQiOlt7IkNvbmRpdGlvbiI6eyJEYXRlTGVzc1RoYW4iOnsiQVdTOkVwb2NoVGltZSI6MTczMjE3NTIwMH19LCJSZXNvdXJjZSI6Imh0dHBzOi8vY2RuLWxmcy11cy0xLmhmLmNvL3JlcG9zLzEzLzIyLzEzMjI5ZDg4OTg3MmEyNzcyODEzNDEwNWY4MzQ5YThiMjNjODQ3MDhmZTUxOWY1NWMyYjA4ZTg1OGYyMTMyMmEvZGQ2YjZlNGY1MmRiMGE3YWZmODNhMTNkMTBlNmM1MzQyZWY5ZjZhYjc5OWJhZDMyMjFmNGIzNWVmMzkwZmE4NT9yZXNwb25zZS1jb250ZW50LWRpc3Bvc2l0aW9uPSoifV19&Signature=QwV-piqTSZ2n6hmj665n-y-NizdDoer4rPNs6xNgcwskGRGTrF561Fvjxt9Uhcr5HIy0cj-1X80xkPW5MAQ021x-PtIhJIlEPg1Sk4YynyaLXuDQ9VKMlEzIOvju1gM4v0-1HGniXXRaDLdxERL4P-R04G7-09QCLRbuxz8khn3TEIYd1ag6WamNSzBmwUSuBh8I89xKRIGD77Gowx7WHaw6yCshkzkYtlteALc4mgCOupHwRDPE3IDU7qfKXgpObsTPOdGyH4sfLyiNBJyEryvoqQ8F~qQAkGYdZGL54U~UnPI36QJshxoFiFsqAGzAuuwZWmeGVdi6QfAaPn2-Jw__&Key-Pair-Id=K24J24Z295AEI9 HTTP/11" 200 1119825680
2024-11-18 07:48:17 [DEBUG] filelock (_api): Attempting to release lock 123388994670848 on /home/zxc/.cache/huggingface/hub/.locks/models--intfloat--multilingual-e5-large-instruct/dd6b6e4f52db0a7aff83a13d10e6c5342ef9f6ab799bad3221f4b35ef390fa85.lock
2024-11-18 07:48:17 [DEBUG] filelock (_api): Lock 123388994670848 released on /home/zxc/.cache/huggingface/hub/.locks/models--intfloat--multilingual-e5-large-instruct/dd6b6e4f52db0a7aff83a13d10e6c5342ef9f6ab799bad3221f4b35ef390fa85.lock
2024-11-18 07:48:18 [DEBUG] urllib3.connectionpool (connectionpool): https://huggingface.co:443 "HEAD /intfloat/multilingual-e5-large-instruct/resolve/main/tokenizer_config.json HTTP/11" 200 0
2024-11-18 07:48:18 [DEBUG] filelock (_api): Attempting to acquire lock 123388995705296 on /home/zxc/.cache/huggingface/hub/.locks/models--intfloat--multilingual-e5-large-instruct/bc9cb006ea6982868d4e32f58506b1d17873b21f.lock
2024-11-18 07:48:18 [DEBUG] filelock (_api): Lock 123388995705296 acquired on /home/zxc/.cache/huggingface/hub/.locks/models--intfloat--multilingual-e5-large-instruct/bc9cb006ea6982868d4e32f58506b1d17873b21f.lock
2024-11-18 07:48:19 [DEBUG] urllib3.connectionpool (connectionpool): https://huggingface.co:443 "GET /intfloat/multilingual-e5-large-instruct/resolve/main/tokenizer_config.json HTTP/11" 200 1182
2024-11-18 07:48:19 [DEBUG] filelock (_api): Attempting to release lock 123388995705296 on /home/zxc/.cache/huggingface/hub/.locks/models--intfloat--multilingual-e5-large-instruct/bc9cb006ea6982868d4e32f58506b1d17873b21f.lock
2024-11-18 07:48:19 [DEBUG] filelock (_api): Lock 123388995705296 released on /home/zxc/.cache/huggingface/hub/.locks/models--intfloat--multilingual-e5-large-instruct/bc9cb006ea6982868d4e32f58506b1d17873b21f.lock
2024-11-18 07:48:19 [DEBUG] urllib3.connectionpool (connectionpool): https://huggingface.co:443 "HEAD /intfloat/multilingual-e5-large-instruct/resolve/main/sentencepiece.bpe.model HTTP/11" 302 0
2024-11-18 07:48:19 [DEBUG] filelock (_api): Attempting to acquire lock 123388994625056 on /home/zxc/.cache/huggingface/hub/.locks/models--intfloat--multilingual-e5-large-instruct/cfc8146abe2a0488e9e2a0c56de7952f7c11ab059eca145a0a727afce0db2865.lock
2024-11-18 07:48:19 [DEBUG] filelock (_api): Lock 123388994625056 acquired on /home/zxc/.cache/huggingface/hub/.locks/models--intfloat--multilingual-e5-large-instruct/cfc8146abe2a0488e9e2a0c56de7952f7c11ab059eca145a0a727afce0db2865.lock
2024-11-18 07:48:19 [DEBUG] urllib3.connectionpool (connectionpool): https://cdn-lfs-us-1.hf.co:443 "GET /repos/13/22/13229d889872a27728134105f8349a8b23c84708fe519f55c2b08e858f21322a/cfc8146abe2a0488e9e2a0c56de7952f7c11ab059eca145a0a727afce0db2865?response-content-disposition=inline%3B+filename*%3DUTF-8%27%27sentencepiece.bpe.model%3B+filename%3D%22sentencepiece.bpe.model%22%3B&Expires=1732175299&Policy=eyJTdGF0ZW1lbnQiOlt7IkNvbmRpdGlvbiI6eyJEYXRlTGVzc1RoYW4iOnsiQVdTOkVwb2NoVGltZSI6MTczMjE3NTI5OX19LCJSZXNvdXJjZSI6Imh0dHBzOi8vY2RuLWxmcy11cy0xLmhmLmNvL3JlcG9zLzEzLzIyLzEzMjI5ZDg4OTg3MmEyNzcyODEzNDEwNWY4MzQ5YThiMjNjODQ3MDhmZTUxOWY1NWMyYjA4ZTg1OGYyMTMyMmEvY2ZjODE0NmFiZTJhMDQ4OGU5ZTJhMGM1NmRlNzk1MmY3YzExYWIwNTllY2ExNDVhMGE3MjdhZmNlMGRiMjg2NT9yZXNwb25zZS1jb250ZW50LWRpc3Bvc2l0aW9uPSoifV19&Signature=aGp89uK1-T8jL1q-~RLeHX0FdqGZfcGrs6pCosqhK9Ip0pr06qi3h3jgLmti7t0zy68NqMdXgtBun7-8L5417N7uAfHGmaBKkguc9VQ8-lzKesdxifWdZy85qF7KxEr0q9MXc-kJ0EPs-P9qUZyKQZaBWIXg0kbFoyiP~F3bcwkk46FlevNCJYpvAqx8KGXWo3T8b2TbrvwavL4w5N8z1alErXReWei9HJdyB2ClmHssr0mWEdKY36Btl9TvSUxgQ3CFUAKFlaJAQKgXodjraAgRUADuRj1je5-~234tIA6QMFvNSkNztooSQfOuKN7GOkz6jBlAwaCevzNfcRG0zQ__&Key-Pair-Id=K24J24Z295AEI9 HTTP/11" 200 5069051
2024-11-18 07:48:20 [DEBUG] filelock (_api): Attempting to release lock 123388994625056 on /home/zxc/.cache/huggingface/hub/.locks/models--intfloat--multilingual-e5-large-instruct/cfc8146abe2a0488e9e2a0c56de7952f7c11ab059eca145a0a727afce0db2865.lock
2024-11-18 07:48:20 [DEBUG] filelock (_api): Lock 123388994625056 released on /home/zxc/.cache/huggingface/hub/.locks/models--intfloat--multilingual-e5-large-instruct/cfc8146abe2a0488e9e2a0c56de7952f7c11ab059eca145a0a727afce0db2865.lock
2024-11-18 07:48:20 [DEBUG] urllib3.connectionpool (connectionpool): https://huggingface.co:443 "HEAD /intfloat/multilingual-e5-large-instruct/resolve/main/tokenizer.json HTTP/11" 302 0
2024-11-18 07:48:20 [DEBUG] filelock (_api): Attempting to acquire lock 123388975223472 on /home/zxc/.cache/huggingface/hub/.locks/models--intfloat--multilingual-e5-large-instruct/f59925fcb90c92b894cb93e51bb9b4a6105c5c249fe54ce1c704420ac39b81af.lock
2024-11-18 07:48:20 [DEBUG] filelock (_api): Lock 123388975223472 acquired on /home/zxc/.cache/huggingface/hub/.locks/models--intfloat--multilingual-e5-large-instruct/f59925fcb90c92b894cb93e51bb9b4a6105c5c249fe54ce1c704420ac39b81af.lock
2024-11-18 07:48:20 [DEBUG] urllib3.connectionpool (connectionpool): https://cdn-lfs-us-1.hf.co:443 "GET /repos/13/22/13229d889872a27728134105f8349a8b23c84708fe519f55c2b08e858f21322a/f59925fcb90c92b894cb93e51bb9b4a6105c5c249fe54ce1c704420ac39b81af?response-content-disposition=inline%3B+filename*%3DUTF-8%27%27tokenizer.json%3B+filename%3D%22tokenizer.json%22%3B&response-content-type=application%2Fjson&Expires=1732175300&Policy=eyJTdGF0ZW1lbnQiOlt7IkNvbmRpdGlvbiI6eyJEYXRlTGVzc1RoYW4iOnsiQVdTOkVwb2NoVGltZSI6MTczMjE3NTMwMH19LCJSZXNvdXJjZSI6Imh0dHBzOi8vY2RuLWxmcy11cy0xLmhmLmNvL3JlcG9zLzEzLzIyLzEzMjI5ZDg4OTg3MmEyNzcyODEzNDEwNWY4MzQ5YThiMjNjODQ3MDhmZTUxOWY1NWMyYjA4ZTg1OGYyMTMyMmEvZjU5OTI1ZmNiOTBjOTJiODk0Y2I5M2U1MWJiOWI0YTYxMDVjNWMyNDlmZTU0Y2UxYzcwNDQyMGFjMzliODFhZj9yZXNwb25zZS1jb250ZW50LWRpc3Bvc2l0aW9uPSomcmVzcG9uc2UtY29udGVudC10eXBlPSoifV19&Signature=BtZ-yxA65LSRCUDFOI-L3oB8-K6ORiyzq2gduD5qxhYtQpRZ1syuVMZkCxhVjuhzYCw~rKbiAUCua9wxNbvFKZYldu-dJVq3YARVAMXQMdrXKadaV9SCGW3cZRmFnnHcgUSIGot1uwams~VU8Comejb6mFF7LegL-QClAj15Z461e7y2ELiSv~kRJDmFSw~oaZiRhT9QvgGZXLLoeHlBExdqPuR9PV2vcZhzArAkRLGunfwjsWr5ToK9-QG7w5VZBVvTjwdmZqIDqcrKoeQ~dXYcKZF79vSQ0tdK0v2uEL7587po846f8~q5AOjdvEBnNrrSJ0QLAUIV~CrCUC~huQ__&Key-Pair-Id=K24J24Z295AEI9 HTTP/11" 200 17082756
2024-11-18 07:48:21 [DEBUG] filelock (_api): Attempting to release lock 123388975223472 on /home/zxc/.cache/huggingface/hub/.locks/models--intfloat--multilingual-e5-large-instruct/f59925fcb90c92b894cb93e51bb9b4a6105c5c249fe54ce1c704420ac39b81af.lock
2024-11-18 07:48:21 [DEBUG] filelock (_api): Lock 123388975223472 released on /home/zxc/.cache/huggingface/hub/.locks/models--intfloat--multilingual-e5-large-instruct/f59925fcb90c92b894cb93e51bb9b4a6105c5c249fe54ce1c704420ac39b81af.lock
2024-11-18 07:48:22 [DEBUG] urllib3.connectionpool (connectionpool): https://huggingface.co:443 "HEAD /intfloat/multilingual-e5-large-instruct/resolve/main/added_tokens.json HTTP/11" 404 0
2024-11-18 07:48:22 [DEBUG] urllib3.connectionpool (connectionpool): https://huggingface.co:443 "HEAD /intfloat/multilingual-e5-large-instruct/resolve/main/special_tokens_map.json HTTP/11" 200 0
2024-11-18 07:48:22 [DEBUG] filelock (_api): Attempting to acquire lock 123388975230192 on /home/zxc/.cache/huggingface/hub/.locks/models--intfloat--multilingual-e5-large-instruct/b1879d702821e753ffe4245048eee415d54a9385.lock
2024-11-18 07:48:22 [DEBUG] filelock (_api): Lock 123388975230192 acquired on /home/zxc/.cache/huggingface/hub/.locks/models--intfloat--multilingual-e5-large-instruct/b1879d702821e753ffe4245048eee415d54a9385.lock
2024-11-18 07:48:22 [DEBUG] urllib3.connectionpool (connectionpool): https://huggingface.co:443 "GET /intfloat/multilingual-e5-large-instruct/resolve/main/special_tokens_map.json HTTP/11" 200 964
2024-11-18 07:48:22 [DEBUG] filelock (_api): Attempting to release lock 123388975230192 on /home/zxc/.cache/huggingface/hub/.locks/models--intfloat--multilingual-e5-large-instruct/b1879d702821e753ffe4245048eee415d54a9385.lock
2024-11-18 07:48:22 [DEBUG] filelock (_api): Lock 123388975230192 released on /home/zxc/.cache/huggingface/hub/.locks/models--intfloat--multilingual-e5-large-instruct/b1879d702821e753ffe4245048eee415d54a9385.lock
2024-11-18 07:48:23 [DEBUG] urllib3.connectionpool (connectionpool): https://huggingface.co:443 "GET /api/models/intfloat/multilingual-e5-large-instruct/revision/main HTTP/11" 200 285774
2024-11-18 07:48:23 [DEBUG] urllib3.connectionpool (connectionpool): Starting new HTTPS connection (1): huggingface.co:443
2024-11-18 07:48:23 [DEBUG] urllib3.connectionpool (connectionpool): https://huggingface.co:443 "HEAD /intfloat/multilingual-e5-large-instruct/resolve/c9e87c786ffac96aeaeb42863276930883923ecb/1_Pooling/config.json HTTP/11" 200 0
2024-11-18 07:48:23 [DEBUG] filelock (_api): Attempting to acquire lock 123388896857456 on /home/zxc/.cache/huggingface/hub/.locks/models--intfloat--multilingual-e5-large-instruct/c5bf064bf9373d01df9cfe9437084f3bd5d33b14.lock
2024-11-18 07:48:23 [DEBUG] filelock (_api): Lock 123388896857456 acquired on /home/zxc/.cache/huggingface/hub/.locks/models--intfloat--multilingual-e5-large-instruct/c5bf064bf9373d01df9cfe9437084f3bd5d33b14.lock
2024-11-18 07:48:24 [DEBUG] urllib3.connectionpool (connectionpool): https://huggingface.co:443 "GET /intfloat/multilingual-e5-large-instruct/resolve/c9e87c786ffac96aeaeb42863276930883923ecb/1_Pooling/config.json HTTP/11" 200 271
2024-11-18 07:48:24 [DEBUG] filelock (_api): Attempting to release lock 123388896857456 on /home/zxc/.cache/huggingface/hub/.locks/models--intfloat--multilingual-e5-large-instruct/c5bf064bf9373d01df9cfe9437084f3bd5d33b14.lock
2024-11-18 07:48:24 [DEBUG] filelock (_api): Lock 123388896857456 released on /home/zxc/.cache/huggingface/hub/.locks/models--intfloat--multilingual-e5-large-instruct/c5bf064bf9373d01df9cfe9437084f3bd5d33b14.lock
2024-11-18 07:48:24 [DEBUG] urllib3.connectionpool (connectionpool): https://huggingface.co:443 "GET /api/models/intfloat/multilingual-e5-large-instruct HTTP/11" 200 285774
2024-11-18 08:12:39 [INFO] django.utils.autoreload (autoreload): Watching for file changes with StatReloader
2024-11-18 08:12:40 [DEBUG] faiss.loader (loader): Environment variable FAISS_OPT_LEVEL is not set, so let's pick the instruction set according to the current CPU
2024-11-18 08:12:40 [INFO] faiss.loader (loader): Loading faiss with AVX2 support.
2024-11-18 08:12:40 [INFO] faiss.loader (loader): Successfully loaded faiss with AVX2 support.
2024-11-18 08:12:55 [INFO] sentence_transformers.SentenceTransformer (SentenceTransformer): Use pytorch device_name: cpu
2024-11-18 08:12:55 [INFO] sentence_transformers.SentenceTransformer (SentenceTransformer): Load pretrained SentenceTransformer: intfloat/multilingual-e5-large-instruct
2024-11-18 08:12:55 [DEBUG] urllib3.connectionpool (connectionpool): Starting new HTTPS connection (1): huggingface.co:443
2024-11-18 08:12:56 [DEBUG] urllib3.connectionpool (connectionpool): https://huggingface.co:443 "HEAD /intfloat/multilingual-e5-large-instruct/resolve/main/modules.json HTTP/11" 200 0
2024-11-18 08:12:56 [DEBUG] urllib3.connectionpool (connectionpool): https://huggingface.co:443 "HEAD /intfloat/multilingual-e5-large-instruct/resolve/main/config_sentence_transformers.json HTTP/11" 200 0
2024-11-18 08:12:56 [DEBUG] urllib3.connectionpool (connectionpool): https://huggingface.co:443 "HEAD /intfloat/multilingual-e5-large-instruct/resolve/main/README.md HTTP/11" 200 0
2024-11-18 08:12:56 [DEBUG] urllib3.connectionpool (connectionpool): https://huggingface.co:443 "HEAD /intfloat/multilingual-e5-large-instruct/resolve/main/modules.json HTTP/11" 200 0
2024-11-18 08:12:57 [DEBUG] urllib3.connectionpool (connectionpool): https://huggingface.co:443 "HEAD /intfloat/multilingual-e5-large-instruct/resolve/main/sentence_bert_config.json HTTP/11" 404 0
2024-11-18 08:12:57 [DEBUG] urllib3.connectionpool (connectionpool): https://huggingface.co:443 "HEAD /intfloat/multilingual-e5-large-instruct/resolve/main/sentence_roberta_config.json HTTP/11" 404 0
2024-11-18 08:12:57 [DEBUG] urllib3.connectionpool (connectionpool): https://huggingface.co:443 "HEAD /intfloat/multilingual-e5-large-instruct/resolve/main/sentence_distilbert_config.json HTTP/11" 404 0
2024-11-18 08:12:57 [DEBUG] urllib3.connectionpool (connectionpool): https://huggingface.co:443 "HEAD /intfloat/multilingual-e5-large-instruct/resolve/main/sentence_camembert_config.json HTTP/11" 404 0
2024-11-18 08:12:58 [DEBUG] urllib3.connectionpool (connectionpool): https://huggingface.co:443 "HEAD /intfloat/multilingual-e5-large-instruct/resolve/main/sentence_albert_config.json HTTP/11" 404 0
2024-11-18 08:12:58 [DEBUG] urllib3.connectionpool (connectionpool): https://huggingface.co:443 "HEAD /intfloat/multilingual-e5-large-instruct/resolve/main/sentence_xlm-roberta_config.json HTTP/11" 404 0
2024-11-18 08:12:58 [DEBUG] urllib3.connectionpool (connectionpool): https://huggingface.co:443 "HEAD /intfloat/multilingual-e5-large-instruct/resolve/main/sentence_xlnet_config.json HTTP/11" 404 0
2024-11-18 08:12:58 [DEBUG] urllib3.connectionpool (connectionpool): https://huggingface.co:443 "HEAD /intfloat/multilingual-e5-large-instruct/resolve/main/adapter_config.json HTTP/11" 404 0
2024-11-18 08:12:58 [DEBUG] urllib3.connectionpool (connectionpool): https://huggingface.co:443 "HEAD /intfloat/multilingual-e5-large-instruct/resolve/main/config.json HTTP/11" 200 0
2024-11-18 08:12:59 [DEBUG] urllib3.connectionpool (connectionpool): https://huggingface.co:443 "HEAD /intfloat/multilingual-e5-large-instruct/resolve/main/tokenizer_config.json HTTP/11" 200 0
2024-11-18 08:13:00 [DEBUG] urllib3.connectionpool (connectionpool): https://huggingface.co:443 "GET /api/models/intfloat/multilingual-e5-large-instruct/revision/main HTTP/11" 200 285774
2024-11-18 08:13:01 [DEBUG] urllib3.connectionpool (connectionpool): https://huggingface.co:443 "GET /api/models/intfloat/multilingual-e5-large-instruct HTTP/11" 200 285774
2024-11-18 08:20:54 [INFO] sentence_transformers.SentenceTransformer (SentenceTransformer): Use pytorch device_name: cpu
2024-11-18 08:20:54 [INFO] sentence_transformers.SentenceTransformer (SentenceTransformer): Load pretrained SentenceTransformer: intfloat/multilingual-e5-large-instruct
2024-11-18 08:20:54 [DEBUG] urllib3.connectionpool (connectionpool): Starting new HTTPS connection (1): huggingface.co:443
2024-11-18 08:20:54 [DEBUG] urllib3.connectionpool (connectionpool): https://huggingface.co:443 "HEAD /intfloat/multilingual-e5-large-instruct/resolve/main/modules.json HTTP/11" 200 0
2024-11-18 08:20:55 [DEBUG] urllib3.connectionpool (connectionpool): https://huggingface.co:443 "HEAD /intfloat/multilingual-e5-large-instruct/resolve/main/config_sentence_transformers.json HTTP/11" 200 0
2024-11-18 08:20:55 [DEBUG] urllib3.connectionpool (connectionpool): https://huggingface.co:443 "HEAD /intfloat/multilingual-e5-large-instruct/resolve/main/README.md HTTP/11" 200 0
2024-11-18 08:20:55 [DEBUG] urllib3.connectionpool (connectionpool): https://huggingface.co:443 "HEAD /intfloat/multilingual-e5-large-instruct/resolve/main/modules.json HTTP/11" 200 0
2024-11-18 08:20:55 [DEBUG] urllib3.connectionpool (connectionpool): https://huggingface.co:443 "HEAD /intfloat/multilingual-e5-large-instruct/resolve/main/sentence_bert_config.json HTTP/11" 404 0
2024-11-18 08:20:55 [DEBUG] urllib3.connectionpool (connectionpool): https://huggingface.co:443 "HEAD /intfloat/multilingual-e5-large-instruct/resolve/main/sentence_roberta_config.json HTTP/11" 404 0
2024-11-18 08:20:56 [DEBUG] urllib3.connectionpool (connectionpool): https://huggingface.co:443 "HEAD /intfloat/multilingual-e5-large-instruct/resolve/main/sentence_distilbert_config.json HTTP/11" 404 0
2024-11-18 08:20:56 [DEBUG] urllib3.connectionpool (connectionpool): https://huggingface.co:443 "HEAD /intfloat/multilingual-e5-large-instruct/resolve/main/sentence_camembert_config.json HTTP/11" 404 0
2024-11-18 08:20:56 [DEBUG] urllib3.connectionpool (connectionpool): https://huggingface.co:443 "HEAD /intfloat/multilingual-e5-large-instruct/resolve/main/sentence_albert_config.json HTTP/11" 404 0
2024-11-18 08:20:56 [DEBUG] urllib3.connectionpool (connectionpool): https://huggingface.co:443 "HEAD /intfloat/multilingual-e5-large-instruct/resolve/main/sentence_xlm-roberta_config.json HTTP/11" 404 0
2024-11-18 08:20:57 [DEBUG] urllib3.connectionpool (connectionpool): https://huggingface.co:443 "HEAD /intfloat/multilingual-e5-large-instruct/resolve/main/sentence_xlnet_config.json HTTP/11" 404 0
2024-11-18 08:20:57 [DEBUG] urllib3.connectionpool (connectionpool): https://huggingface.co:443 "HEAD /intfloat/multilingual-e5-large-instruct/resolve/main/adapter_config.json HTTP/11" 404 0
2024-11-18 08:20:57 [DEBUG] urllib3.connectionpool (connectionpool): https://huggingface.co:443 "HEAD /intfloat/multilingual-e5-large-instruct/resolve/main/config.json HTTP/11" 200 0
2024-11-18 08:20:58 [DEBUG] urllib3.connectionpool (connectionpool): https://huggingface.co:443 "HEAD /intfloat/multilingual-e5-large-instruct/resolve/main/tokenizer_config.json HTTP/11" 200 0
2024-11-18 08:20:59 [DEBUG] urllib3.connectionpool (connectionpool): https://huggingface.co:443 "GET /api/models/intfloat/multilingual-e5-large-instruct/revision/main HTTP/11" 200 285774
2024-11-18 08:20:59 [DEBUG] urllib3.connectionpool (connectionpool): https://huggingface.co:443 "GET /api/models/intfloat/multilingual-e5-large-instruct HTTP/11" 200 285774
2024-11-18 08:27:22 [INFO] sentence_transformers.SentenceTransformer (SentenceTransformer): Use pytorch device_name: cpu
2024-11-18 08:27:22 [INFO] sentence_transformers.SentenceTransformer (SentenceTransformer): Load pretrained SentenceTransformer: intfloat/multilingual-e5-large-instruct
2024-11-18 08:27:22 [DEBUG] urllib3.connectionpool (connectionpool): Starting new HTTPS connection (1): huggingface.co:443
2024-11-18 08:27:22 [DEBUG] urllib3.connectionpool (connectionpool): https://huggingface.co:443 "HEAD /intfloat/multilingual-e5-large-instruct/resolve/main/modules.json HTTP/11" 200 0
2024-11-18 08:27:22 [DEBUG] urllib3.connectionpool (connectionpool): https://huggingface.co:443 "HEAD /intfloat/multilingual-e5-large-instruct/resolve/main/config_sentence_transformers.json HTTP/11" 200 0
2024-11-18 08:27:22 [DEBUG] urllib3.connectionpool (connectionpool): https://huggingface.co:443 "HEAD /intfloat/multilingual-e5-large-instruct/resolve/main/README.md HTTP/11" 200 0
2024-11-18 08:27:23 [DEBUG] urllib3.connectionpool (connectionpool): https://huggingface.co:443 "HEAD /intfloat/multilingual-e5-large-instruct/resolve/main/modules.json HTTP/11" 200 0
2024-11-18 08:27:23 [DEBUG] urllib3.connectionpool (connectionpool): https://huggingface.co:443 "HEAD /intfloat/multilingual-e5-large-instruct/resolve/main/sentence_bert_config.json HTTP/11" 404 0
2024-11-18 08:27:23 [DEBUG] urllib3.connectionpool (connectionpool): https://huggingface.co:443 "HEAD /intfloat/multilingual-e5-large-instruct/resolve/main/sentence_roberta_config.json HTTP/11" 404 0
2024-11-18 08:27:23 [DEBUG] urllib3.connectionpool (connectionpool): https://huggingface.co:443 "HEAD /intfloat/multilingual-e5-large-instruct/resolve/main/sentence_distilbert_config.json HTTP/11" 404 0
2024-11-18 08:27:23 [DEBUG] urllib3.connectionpool (connectionpool): https://huggingface.co:443 "HEAD /intfloat/multilingual-e5-large-instruct/resolve/main/sentence_camembert_config.json HTTP/11" 404 0
2024-11-18 08:27:24 [DEBUG] urllib3.connectionpool (connectionpool): https://huggingface.co:443 "HEAD /intfloat/multilingual-e5-large-instruct/resolve/main/sentence_albert_config.json HTTP/11" 404 0
2024-11-18 08:27:24 [DEBUG] urllib3.connectionpool (connectionpool): https://huggingface.co:443 "HEAD /intfloat/multilingual-e5-large-instruct/resolve/main/sentence_xlm-roberta_config.json HTTP/11" 404 0
2024-11-18 08:27:24 [DEBUG] urllib3.connectionpool (connectionpool): https://huggingface.co:443 "HEAD /intfloat/multilingual-e5-large-instruct/resolve/main/sentence_xlnet_config.json HTTP/11" 404 0
2024-11-18 08:27:24 [DEBUG] urllib3.connectionpool (connectionpool): https://huggingface.co:443 "HEAD /intfloat/multilingual-e5-large-instruct/resolve/main/adapter_config.json HTTP/11" 404 0
2024-11-18 08:27:24 [DEBUG] urllib3.connectionpool (connectionpool): https://huggingface.co:443 "HEAD /intfloat/multilingual-e5-large-instruct/resolve/main/config.json HTTP/11" 200 0
2024-11-18 08:27:26 [DEBUG] urllib3.connectionpool (connectionpool): https://huggingface.co:443 "HEAD /intfloat/multilingual-e5-large-instruct/resolve/main/tokenizer_config.json HTTP/11" 200 0
2024-11-18 08:27:27 [DEBUG] urllib3.connectionpool (connectionpool): https://huggingface.co:443 "GET /api/models/intfloat/multilingual-e5-large-instruct/revision/main HTTP/11" 200 285774
2024-11-18 08:27:27 [DEBUG] urllib3.connectionpool (connectionpool): https://huggingface.co:443 "GET /api/models/intfloat/multilingual-e5-large-instruct HTTP/11" 200 285774
2024-11-18 08:34:08 [INFO] sentence_transformers.SentenceTransformer (SentenceTransformer): Use pytorch device_name: cpu
2024-11-18 08:34:08 [INFO] sentence_transformers.SentenceTransformer (SentenceTransformer): Load pretrained SentenceTransformer: intfloat/multilingual-e5-large-instruct
2024-11-18 08:34:08 [DEBUG] urllib3.connectionpool (connectionpool): Starting new HTTPS connection (1): huggingface.co:443
2024-11-18 08:34:09 [DEBUG] urllib3.connectionpool (connectionpool): https://huggingface.co:443 "HEAD /intfloat/multilingual-e5-large-instruct/resolve/main/modules.json HTTP/11" 200 0
2024-11-18 08:34:09 [DEBUG] urllib3.connectionpool (connectionpool): https://huggingface.co:443 "HEAD /intfloat/multilingual-e5-large-instruct/resolve/main/config_sentence_transformers.json HTTP/11" 200 0
2024-11-18 08:34:09 [DEBUG] urllib3.connectionpool (connectionpool): https://huggingface.co:443 "HEAD /intfloat/multilingual-e5-large-instruct/resolve/main/README.md HTTP/11" 200 0
2024-11-18 08:34:10 [DEBUG] urllib3.connectionpool (connectionpool): https://huggingface.co:443 "HEAD /intfloat/multilingual-e5-large-instruct/resolve/main/modules.json HTTP/11" 200 0
2024-11-18 08:34:10 [DEBUG] urllib3.connectionpool (connectionpool): https://huggingface.co:443 "HEAD /intfloat/multilingual-e5-large-instruct/resolve/main/sentence_bert_config.json HTTP/11" 404 0
2024-11-18 08:34:10 [DEBUG] urllib3.connectionpool (connectionpool): https://huggingface.co:443 "HEAD /intfloat/multilingual-e5-large-instruct/resolve/main/sentence_roberta_config.json HTTP/11" 404 0
2024-11-18 08:34:10 [DEBUG] urllib3.connectionpool (connectionpool): https://huggingface.co:443 "HEAD /intfloat/multilingual-e5-large-instruct/resolve/main/sentence_distilbert_config.json HTTP/11" 404 0
2024-11-18 08:34:11 [DEBUG] urllib3.connectionpool (connectionpool): https://huggingface.co:443 "HEAD /intfloat/multilingual-e5-large-instruct/resolve/main/sentence_camembert_config.json HTTP/11" 404 0
2024-11-18 08:34:11 [DEBUG] urllib3.connectionpool (connectionpool): https://huggingface.co:443 "HEAD /intfloat/multilingual-e5-large-instruct/resolve/main/sentence_albert_config.json HTTP/11" 404 0
2024-11-18 08:34:11 [DEBUG] urllib3.connectionpool (connectionpool): https://huggingface.co:443 "HEAD /intfloat/multilingual-e5-large-instruct/resolve/main/sentence_xlm-roberta_config.json HTTP/11" 404 0
2024-11-18 08:34:11 [DEBUG] urllib3.connectionpool (connectionpool): https://huggingface.co:443 "HEAD /intfloat/multilingual-e5-large-instruct/resolve/main/sentence_xlnet_config.json HTTP/11" 404 0
2024-11-18 08:34:12 [DEBUG] urllib3.connectionpool (connectionpool): https://huggingface.co:443 "HEAD /intfloat/multilingual-e5-large-instruct/resolve/main/adapter_config.json HTTP/11" 404 0
2024-11-18 08:34:12 [DEBUG] urllib3.connectionpool (connectionpool): https://huggingface.co:443 "HEAD /intfloat/multilingual-e5-large-instruct/resolve/main/config.json HTTP/11" 200 0
2024-11-18 08:34:15 [DEBUG] urllib3.connectionpool (connectionpool): https://huggingface.co:443 "HEAD /intfloat/multilingual-e5-large-instruct/resolve/main/tokenizer_config.json HTTP/11" 200 0
2024-11-18 08:34:16 [DEBUG] urllib3.connectionpool (connectionpool): https://huggingface.co:443 "GET /api/models/intfloat/multilingual-e5-large-instruct/revision/main HTTP/11" 200 285774
2024-11-18 08:34:16 [DEBUG] urllib3.connectionpool (connectionpool): https://huggingface.co:443 "GET /api/models/intfloat/multilingual-e5-large-instruct HTTP/11" 200 285774
2024-11-18 08:45:13 [INFO] api.views (views): Fetching all comments.
2024-11-18 08:45:13 [INFO] api.views (views): Fetched festival with ID 6. View count incremented.
2024-11-18 08:45:13 [INFO] api.views (views): Fetching all hashtags.
2024-11-18 08:48:43 [INFO] api.views (views): Fetching all comments.
2024-11-18 08:48:43 [INFO] api.views (views): Fetched festival with ID 6. View count incremented.
2024-11-18 08:48:43 [INFO] api.views (views): Fetching all hashtags.
2024-11-18 08:49:25 [INFO] api.views (views): Fetching all comments.
2024-11-18 08:49:25 [INFO] api.views (views): Fetched festival with ID 6. View count incremented.
2024-11-18 08:49:25 [INFO] api.views (views): Fetching all hashtags.
2024-11-18 08:49:36 [INFO] api.views (views): Fetching all comments.
2024-11-18 08:49:36 [INFO] api.views (views): Fetched festival with ID 15. View count incremented.
2024-11-18 08:49:36 [INFO] api.views (views): Fetching all hashtags.
2024-11-18 08:49:46 [INFO] sentence_transformers.SentenceTransformer (SentenceTransformer): Use pytorch device_name: cpu
2024-11-18 08:49:46 [INFO] sentence_transformers.SentenceTransformer (SentenceTransformer): Load pretrained SentenceTransformer: intfloat/multilingual-e5-large-instruct
2024-11-18 08:49:46 [DEBUG] urllib3.connectionpool (connectionpool): Starting new HTTPS connection (1): huggingface.co:443
2024-11-18 08:49:47 [DEBUG] urllib3.connectionpool (connectionpool): https://huggingface.co:443 "HEAD /intfloat/multilingual-e5-large-instruct/resolve/main/modules.json HTTP/11" 200 0
2024-11-18 08:49:47 [DEBUG] urllib3.connectionpool (connectionpool): https://huggingface.co:443 "HEAD /intfloat/multilingual-e5-large-instruct/resolve/main/config_sentence_transformers.json HTTP/11" 200 0
2024-11-18 08:49:47 [DEBUG] urllib3.connectionpool (connectionpool): https://huggingface.co:443 "HEAD /intfloat/multilingual-e5-large-instruct/resolve/main/README.md HTTP/11" 200 0
2024-11-18 08:49:47 [DEBUG] urllib3.connectionpool (connectionpool): https://huggingface.co:443 "HEAD /intfloat/multilingual-e5-large-instruct/resolve/main/modules.json HTTP/11" 200 0
2024-11-18 08:49:48 [DEBUG] urllib3.connectionpool (connectionpool): https://huggingface.co:443 "HEAD /intfloat/multilingual-e5-large-instruct/resolve/main/sentence_bert_config.json HTTP/11" 404 0
2024-11-18 08:49:48 [DEBUG] urllib3.connectionpool (connectionpool): https://huggingface.co:443 "HEAD /intfloat/multilingual-e5-large-instruct/resolve/main/sentence_roberta_config.json HTTP/11" 404 0
2024-11-18 08:49:48 [DEBUG] urllib3.connectionpool (connectionpool): https://huggingface.co:443 "HEAD /intfloat/multilingual-e5-large-instruct/resolve/main/sentence_distilbert_config.json HTTP/11" 404 0
2024-11-18 08:49:48 [DEBUG] urllib3.connectionpool (connectionpool): https://huggingface.co:443 "HEAD /intfloat/multilingual-e5-large-instruct/resolve/main/sentence_camembert_config.json HTTP/11" 404 0
2024-11-18 08:49:48 [DEBUG] urllib3.connectionpool (connectionpool): https://huggingface.co:443 "HEAD /intfloat/multilingual-e5-large-instruct/resolve/main/sentence_albert_config.json HTTP/11" 404 0
2024-11-18 08:49:49 [DEBUG] urllib3.connectionpool (connectionpool): https://huggingface.co:443 "HEAD /intfloat/multilingual-e5-large-instruct/resolve/main/sentence_xlm-roberta_config.json HTTP/11" 404 0
2024-11-18 08:49:49 [DEBUG] urllib3.connectionpool (connectionpool): https://huggingface.co:443 "HEAD /intfloat/multilingual-e5-large-instruct/resolve/main/sentence_xlnet_config.json HTTP/11" 404 0
2024-11-18 08:49:49 [DEBUG] urllib3.connectionpool (connectionpool): https://huggingface.co:443 "HEAD /intfloat/multilingual-e5-large-instruct/resolve/main/adapter_config.json HTTP/11" 404 0
2024-11-18 08:49:49 [DEBUG] urllib3.connectionpool (connectionpool): https://huggingface.co:443 "HEAD /intfloat/multilingual-e5-large-instruct/resolve/main/config.json HTTP/11" 200 0
2024-11-18 08:49:54 [DEBUG] urllib3.connectionpool (connectionpool): https://huggingface.co:443 "HEAD /intfloat/multilingual-e5-large-instruct/resolve/main/tokenizer_config.json HTTP/11" 200 0
2024-11-18 08:49:55 [DEBUG] urllib3.connectionpool (connectionpool): https://huggingface.co:443 "GET /api/models/intfloat/multilingual-e5-large-instruct/revision/main HTTP/11" 200 285774
2024-11-18 08:49:55 [DEBUG] urllib3.connectionpool (connectionpool): https://huggingface.co:443 "GET /api/models/intfloat/multilingual-e5-large-instruct HTTP/11" 200 285774
2024-11-18 08:50:33 [INFO] api.views (views): Fetching all comments.
2024-11-18 08:50:33 [INFO] api.views (views): Fetched festival with ID 15. View count incremented.
2024-11-18 08:50:33 [INFO] api.views (views): Fetching all hashtags.
2024-11-18 08:50:37 [INFO] api.views (views): Fetching all festivals.
2024-11-18 08:50:39 [INFO] api.views (views): Fetching all comments.
2024-11-18 08:50:39 [INFO] api.views (views): Fetched festival with ID 19. View count incremented.
2024-11-18 08:50:39 [INFO] api.views (views): Fetching all hashtags.
2024-11-18 08:51:05 [INFO] api.views (views): Fetching all comments.
2024-11-18 08:51:05 [INFO] api.views (views): Fetched festival with ID 20. View count incremented.
2024-11-18 08:51:05 [INFO] api.views (views): Fetching all hashtags.
2024-11-18 08:51:58 [INFO] api.views (views): Fetching all comments.
2024-11-18 08:51:58 [INFO] api.views (views): Fetched festival with ID 6. View count incremented.
2024-11-18 08:51:58 [INFO] api.views (views): Fetching all hashtags.
2024-11-18 08:52:32 [INFO] api.views (views): Fetching all comments.
2024-11-18 08:52:32 [INFO] api.views (views): Fetched festival with ID 5. View count incremented.
2024-11-18 08:52:32 [INFO] api.views (views): Fetching all hashtags.
2024-11-18 08:52:43 [INFO] api.views (views): Fetching all comments.
2024-11-18 08:52:43 [INFO] api.views (views): Fetched festival with ID 19. View count incremented.
2024-11-18 08:52:43 [INFO] api.views (views): Fetching all hashtags.
2024-11-19 00:27:14 [DEBUG] faiss.loader (loader): Environment variable FAISS_OPT_LEVEL is not set, so let's pick the instruction set according to the current CPU
2024-11-19 00:27:14 [INFO] faiss.loader (loader): Loading faiss with AVX2 support.
2024-11-19 00:27:14 [INFO] faiss.loader (loader): Successfully loaded faiss with AVX2 support.
2024-11-19 00:27:15 [DEBUG] pydot (__init__): pydot initializing
2024-11-19 00:27:15 [DEBUG] pydot (__init__): pydot 3.0.2
2024-11-19 00:27:15 [DEBUG] pydot.dot_parser (dot_parser): pydot dot_parser module initializing
2024-11-19 00:27:15 [DEBUG] pydot.core (core): pydot core module initializing
2024-11-19 00:27:42 [DEBUG] faiss.loader (loader): Environment variable FAISS_OPT_LEVEL is not set, so let's pick the instruction set according to the current CPU
2024-11-19 00:27:42 [INFO] faiss.loader (loader): Loading faiss with AVX2 support.
2024-11-19 00:27:42 [INFO] faiss.loader (loader): Successfully loaded faiss with AVX2 support.
2024-11-19 00:27:42 [DEBUG] pydot (__init__): pydot initializing
2024-11-19 00:27:42 [DEBUG] pydot (__init__): pydot 3.0.2
2024-11-19 00:27:42 [DEBUG] pydot.dot_parser (dot_parser): pydot dot_parser module initializing
2024-11-19 00:27:42 [DEBUG] pydot.core (core): pydot core module initializing
2024-11-19 00:28:16 [DEBUG] faiss.loader (loader): Environment variable FAISS_OPT_LEVEL is not set, so let's pick the instruction set according to the current CPU
2024-11-19 00:28:16 [INFO] faiss.loader (loader): Loading faiss with AVX2 support.
2024-11-19 00:28:16 [INFO] faiss.loader (loader): Successfully loaded faiss with AVX2 support.
2024-11-19 00:28:17 [DEBUG] pydot (__init__): pydot initializing
2024-11-19 00:28:17 [DEBUG] pydot (__init__): pydot 3.0.2
2024-11-19 00:28:17 [DEBUG] pydot.dot_parser (dot_parser): pydot dot_parser module initializing
2024-11-19 00:28:17 [DEBUG] pydot.core (core): pydot core module initializing
2024-11-19 00:28:30 [DEBUG] faiss.loader (loader): Environment variable FAISS_OPT_LEVEL is not set, so let's pick the instruction set according to the current CPU
2024-11-19 00:28:30 [INFO] faiss.loader (loader): Loading faiss with AVX2 support.
2024-11-19 00:28:30 [INFO] faiss.loader (loader): Successfully loaded faiss with AVX2 support.
2024-11-19 00:28:31 [DEBUG] pydot (__init__): pydot initializing
2024-11-19 00:28:31 [DEBUG] pydot (__init__): pydot 3.0.2
2024-11-19 00:28:31 [DEBUG] pydot.dot_parser (dot_parser): pydot dot_parser module initializing
2024-11-19 00:28:31 [DEBUG] pydot.core (core): pydot core module initializing
2024-11-19 00:29:06 [INFO] django.utils.autoreload (autoreload): Watching for file changes with StatReloader
2024-11-19 00:29:06 [DEBUG] faiss.loader (loader): Environment variable FAISS_OPT_LEVEL is not set, so let's pick the instruction set according to the current CPU
2024-11-19 00:29:06 [INFO] faiss.loader (loader): Loading faiss with AVX2 support.
2024-11-19 00:29:06 [INFO] faiss.loader (loader): Successfully loaded faiss with AVX2 support.
2024-11-19 00:29:07 [DEBUG] pydot (__init__): pydot initializing
2024-11-19 00:29:07 [DEBUG] pydot (__init__): pydot 3.0.2
2024-11-19 00:29:07 [DEBUG] pydot.dot_parser (dot_parser): pydot dot_parser module initializing
2024-11-19 00:29:07 [DEBUG] pydot.core (core): pydot core module initializing
2024-11-19 00:29:11 [WARNING] django.request (log): Not Found: /
2024-11-19 00:29:13 [WARNING] django.request (log): Not Found: /
2024-11-19 00:49:21 [DEBUG] faiss.loader (loader): Environment variable FAISS_OPT_LEVEL is not set, so let's pick the instruction set according to the current CPU
2024-11-19 00:49:21 [INFO] faiss.loader (loader): Loading faiss with AVX2 support.
2024-11-19 00:49:21 [INFO] faiss.loader (loader): Successfully loaded faiss with AVX2 support.
2024-11-19 00:49:21 [DEBUG] pydot (__init__): pydot initializing
2024-11-19 00:49:21 [DEBUG] pydot (__init__): pydot 3.0.2
2024-11-19 00:49:21 [DEBUG] pydot.dot_parser (dot_parser): pydot dot_parser module initializing
2024-11-19 00:49:21 [DEBUG] pydot.core (core): pydot core module initializing
2024-11-19 01:40:04 [DEBUG] faiss.loader (loader): Environment variable FAISS_OPT_LEVEL is not set, so let's pick the instruction set according to the current CPU
2024-11-19 01:40:04 [INFO] faiss.loader (loader): Loading faiss with AVX2 support.
2024-11-19 01:40:04 [INFO] faiss.loader (loader): Successfully loaded faiss with AVX2 support.
2024-11-19 01:40:05 [DEBUG] pydot (__init__): pydot initializing
2024-11-19 01:40:05 [DEBUG] pydot (__init__): pydot 3.0.2
2024-11-19 01:40:05 [DEBUG] pydot.dot_parser (dot_parser): pydot dot_parser module initializing
2024-11-19 01:40:05 [DEBUG] pydot.core (core): pydot core module initializing
2024-11-19 01:40:08 [WARNING] django.request (log): Not Found: /
2024-11-19 02:27:27 [ERROR] django.security.DisallowedHost (exception): Invalid HTTP_HOST header: '43.203.213.169'. You may need to add '43.203.213.169' to ALLOWED_HOSTS.
Traceback (most recent call last):
  File "/home/ubuntu/Festival/venv/lib/python3.12/site-packages/django/core/handlers/exception.py", line 55, in inner
    response = get_response(request)
               ^^^^^^^^^^^^^^^^^^^^^
  File "/home/ubuntu/Festival/venv/lib/python3.12/site-packages/django/utils/deprecation.py", line 128, in __call__
    response = self.process_request(request)
               ^^^^^^^^^^^^^^^^^^^^^^^^^^^^^
  File "/home/ubuntu/Festival/venv/lib/python3.12/site-packages/django/middleware/common.py", line 48, in process_request
    host = request.get_host()
           ^^^^^^^^^^^^^^^^^^
  File "/home/ubuntu/Festival/venv/lib/python3.12/site-packages/django/http/request.py", line 151, in get_host
    raise DisallowedHost(msg)
django.core.exceptions.DisallowedHost: Invalid HTTP_HOST header: '43.203.213.169'. You may need to add '43.203.213.169' to ALLOWED_HOSTS.
2024-11-19 02:27:28 [DEBUG] faiss.loader (loader): Environment variable FAISS_OPT_LEVEL is not set, so let's pick the instruction set according to the current CPU
2024-11-19 02:27:28 [INFO] faiss.loader (loader): Loading faiss with AVX2 support.
2024-11-19 02:27:28 [INFO] faiss.loader (loader): Successfully loaded faiss with AVX2 support.
2024-11-19 02:27:29 [DEBUG] pydot (__init__): pydot initializing
2024-11-19 02:27:29 [DEBUG] pydot (__init__): pydot 3.0.2
2024-11-19 02:27:29 [DEBUG] pydot.dot_parser (dot_parser): pydot dot_parser module initializing
2024-11-19 02:27:29 [DEBUG] pydot.core (core): pydot core module initializing
2024-11-19 02:27:31 [WARNING] django.request (log): Bad Request: /
2024-11-19 02:27:31 [ERROR] django.security.DisallowedHost (exception): Invalid HTTP_HOST header: '43.203.213.169'. You may need to add '43.203.213.169' to ALLOWED_HOSTS.
Traceback (most recent call last):
  File "/home/ubuntu/Festival/venv/lib/python3.12/site-packages/django/core/handlers/exception.py", line 55, in inner
    response = get_response(request)
               ^^^^^^^^^^^^^^^^^^^^^
  File "/home/ubuntu/Festival/venv/lib/python3.12/site-packages/django/utils/deprecation.py", line 128, in __call__
    response = self.process_request(request)
               ^^^^^^^^^^^^^^^^^^^^^^^^^^^^^
  File "/home/ubuntu/Festival/venv/lib/python3.12/site-packages/django/middleware/common.py", line 48, in process_request
    host = request.get_host()
           ^^^^^^^^^^^^^^^^^^
  File "/home/ubuntu/Festival/venv/lib/python3.12/site-packages/django/http/request.py", line 151, in get_host
    raise DisallowedHost(msg)
django.core.exceptions.DisallowedHost: Invalid HTTP_HOST header: '43.203.213.169'. You may need to add '43.203.213.169' to ALLOWED_HOSTS.
2024-11-19 02:27:31 [WARNING] django.request (log): Bad Request: /favicon.ico
2024-11-19 02:28:50 [ERROR] django.security.DisallowedHost (exception): Invalid HTTP_HOST header: '43.203.213.169'. You may need to add '43.203.213.169' to ALLOWED_HOSTS.
Traceback (most recent call last):
  File "/home/ubuntu/Festival/venv/lib/python3.12/site-packages/django/core/handlers/exception.py", line 55, in inner
    response = get_response(request)
               ^^^^^^^^^^^^^^^^^^^^^
  File "/home/ubuntu/Festival/venv/lib/python3.12/site-packages/django/utils/deprecation.py", line 128, in __call__
    response = self.process_request(request)
               ^^^^^^^^^^^^^^^^^^^^^^^^^^^^^
  File "/home/ubuntu/Festival/venv/lib/python3.12/site-packages/django/middleware/common.py", line 48, in process_request
    host = request.get_host()
           ^^^^^^^^^^^^^^^^^^
  File "/home/ubuntu/Festival/venv/lib/python3.12/site-packages/django/http/request.py", line 151, in get_host
    raise DisallowedHost(msg)
django.core.exceptions.DisallowedHost: Invalid HTTP_HOST header: '43.203.213.169'. You may need to add '43.203.213.169' to ALLOWED_HOSTS.
2024-11-19 02:28:50 [WARNING] django.request (log): Bad Request: /
2024-11-19 02:28:50 [ERROR] django.security.DisallowedHost (exception): Invalid HTTP_HOST header: '43.203.213.169'. You may need to add '43.203.213.169' to ALLOWED_HOSTS.
Traceback (most recent call last):
  File "/home/ubuntu/Festival/venv/lib/python3.12/site-packages/django/core/handlers/exception.py", line 55, in inner
    response = get_response(request)
               ^^^^^^^^^^^^^^^^^^^^^
  File "/home/ubuntu/Festival/venv/lib/python3.12/site-packages/django/utils/deprecation.py", line 128, in __call__
    response = self.process_request(request)
               ^^^^^^^^^^^^^^^^^^^^^^^^^^^^^
  File "/home/ubuntu/Festival/venv/lib/python3.12/site-packages/django/middleware/common.py", line 48, in process_request
    host = request.get_host()
           ^^^^^^^^^^^^^^^^^^
  File "/home/ubuntu/Festival/venv/lib/python3.12/site-packages/django/http/request.py", line 151, in get_host
    raise DisallowedHost(msg)
django.core.exceptions.DisallowedHost: Invalid HTTP_HOST header: '43.203.213.169'. You may need to add '43.203.213.169' to ALLOWED_HOSTS.
2024-11-19 02:28:50 [WARNING] django.request (log): Bad Request: /favicon.ico
2024-11-19 02:28:51 [ERROR] django.security.DisallowedHost (exception): Invalid HTTP_HOST header: '43.203.213.169'. You may need to add '43.203.213.169' to ALLOWED_HOSTS.
Traceback (most recent call last):
  File "/home/ubuntu/Festival/venv/lib/python3.12/site-packages/django/core/handlers/exception.py", line 55, in inner
    response = get_response(request)
               ^^^^^^^^^^^^^^^^^^^^^
  File "/home/ubuntu/Festival/venv/lib/python3.12/site-packages/django/utils/deprecation.py", line 128, in __call__
    response = self.process_request(request)
               ^^^^^^^^^^^^^^^^^^^^^^^^^^^^^
  File "/home/ubuntu/Festival/venv/lib/python3.12/site-packages/django/middleware/common.py", line 48, in process_request
    host = request.get_host()
           ^^^^^^^^^^^^^^^^^^
  File "/home/ubuntu/Festival/venv/lib/python3.12/site-packages/django/http/request.py", line 151, in get_host
    raise DisallowedHost(msg)
django.core.exceptions.DisallowedHost: Invalid HTTP_HOST header: '43.203.213.169'. You may need to add '43.203.213.169' to ALLOWED_HOSTS.
2024-11-19 02:28:52 [DEBUG] faiss.loader (loader): Environment variable FAISS_OPT_LEVEL is not set, so let's pick the instruction set according to the current CPU
2024-11-19 02:28:52 [INFO] faiss.loader (loader): Loading faiss with AVX2 support.
2024-11-19 02:28:52 [INFO] faiss.loader (loader): Successfully loaded faiss with AVX2 support.
2024-11-19 02:28:53 [DEBUG] pydot (__init__): pydot initializing
2024-11-19 02:28:53 [DEBUG] pydot (__init__): pydot 3.0.2
2024-11-19 02:28:53 [DEBUG] pydot.dot_parser (dot_parser): pydot dot_parser module initializing
2024-11-19 02:28:53 [DEBUG] pydot.core (core): pydot core module initializing
2024-11-19 02:28:55 [WARNING] django.request (log): Bad Request: /
2024-11-19 02:28:55 [ERROR] django.security.DisallowedHost (exception): Invalid HTTP_HOST header: '43.203.213.169'. You may need to add '43.203.213.169' to ALLOWED_HOSTS.
Traceback (most recent call last):
  File "/home/ubuntu/Festival/venv/lib/python3.12/site-packages/django/core/handlers/exception.py", line 55, in inner
    response = get_response(request)
               ^^^^^^^^^^^^^^^^^^^^^
  File "/home/ubuntu/Festival/venv/lib/python3.12/site-packages/django/utils/deprecation.py", line 128, in __call__
    response = self.process_request(request)
               ^^^^^^^^^^^^^^^^^^^^^^^^^^^^^
  File "/home/ubuntu/Festival/venv/lib/python3.12/site-packages/django/middleware/common.py", line 48, in process_request
    host = request.get_host()
           ^^^^^^^^^^^^^^^^^^
  File "/home/ubuntu/Festival/venv/lib/python3.12/site-packages/django/http/request.py", line 151, in get_host
    raise DisallowedHost(msg)
django.core.exceptions.DisallowedHost: Invalid HTTP_HOST header: '43.203.213.169'. You may need to add '43.203.213.169' to ALLOWED_HOSTS.
2024-11-19 02:28:55 [WARNING] django.request (log): Bad Request: /favicon.ico
2024-11-19 02:28:58 [ERROR] django.security.DisallowedHost (exception): Invalid HTTP_HOST header: '43.203.213.169'. You may need to add '43.203.213.169' to ALLOWED_HOSTS.
Traceback (most recent call last):
  File "/home/ubuntu/Festival/venv/lib/python3.12/site-packages/django/core/handlers/exception.py", line 55, in inner
    response = get_response(request)
               ^^^^^^^^^^^^^^^^^^^^^
  File "/home/ubuntu/Festival/venv/lib/python3.12/site-packages/django/utils/deprecation.py", line 128, in __call__
    response = self.process_request(request)
               ^^^^^^^^^^^^^^^^^^^^^^^^^^^^^
  File "/home/ubuntu/Festival/venv/lib/python3.12/site-packages/django/middleware/common.py", line 48, in process_request
    host = request.get_host()
           ^^^^^^^^^^^^^^^^^^
  File "/home/ubuntu/Festival/venv/lib/python3.12/site-packages/django/http/request.py", line 151, in get_host
    raise DisallowedHost(msg)
django.core.exceptions.DisallowedHost: Invalid HTTP_HOST header: '43.203.213.169'. You may need to add '43.203.213.169' to ALLOWED_HOSTS.
2024-11-19 02:28:58 [WARNING] django.request (log): Bad Request: /
2024-11-19 02:28:58 [ERROR] django.security.DisallowedHost (exception): Invalid HTTP_HOST header: '43.203.213.169'. You may need to add '43.203.213.169' to ALLOWED_HOSTS.
Traceback (most recent call last):
  File "/home/ubuntu/Festival/venv/lib/python3.12/site-packages/django/core/handlers/exception.py", line 55, in inner
    response = get_response(request)
               ^^^^^^^^^^^^^^^^^^^^^
  File "/home/ubuntu/Festival/venv/lib/python3.12/site-packages/django/utils/deprecation.py", line 128, in __call__
    response = self.process_request(request)
               ^^^^^^^^^^^^^^^^^^^^^^^^^^^^^
  File "/home/ubuntu/Festival/venv/lib/python3.12/site-packages/django/middleware/common.py", line 48, in process_request
    host = request.get_host()
           ^^^^^^^^^^^^^^^^^^
  File "/home/ubuntu/Festival/venv/lib/python3.12/site-packages/django/http/request.py", line 151, in get_host
    raise DisallowedHost(msg)
django.core.exceptions.DisallowedHost: Invalid HTTP_HOST header: '43.203.213.169'. You may need to add '43.203.213.169' to ALLOWED_HOSTS.
2024-11-19 02:28:58 [WARNING] django.request (log): Bad Request: /favicon.ico
2024-11-19 02:30:53 [ERROR] django.security.DisallowedHost (exception): Invalid HTTP_HOST header: '43.203.213.169'. You may need to add '43.203.213.169' to ALLOWED_HOSTS.
Traceback (most recent call last):
  File "/home/ubuntu/Festival/venv/lib/python3.12/site-packages/django/core/handlers/exception.py", line 55, in inner
    response = get_response(request)
               ^^^^^^^^^^^^^^^^^^^^^
  File "/home/ubuntu/Festival/venv/lib/python3.12/site-packages/django/utils/deprecation.py", line 128, in __call__
    response = self.process_request(request)
               ^^^^^^^^^^^^^^^^^^^^^^^^^^^^^
  File "/home/ubuntu/Festival/venv/lib/python3.12/site-packages/django/middleware/common.py", line 48, in process_request
    host = request.get_host()
           ^^^^^^^^^^^^^^^^^^
  File "/home/ubuntu/Festival/venv/lib/python3.12/site-packages/django/http/request.py", line 151, in get_host
    raise DisallowedHost(msg)
django.core.exceptions.DisallowedHost: Invalid HTTP_HOST header: '43.203.213.169'. You may need to add '43.203.213.169' to ALLOWED_HOSTS.
2024-11-19 02:30:53 [WARNING] django.request (log): Bad Request: /
2024-11-19 02:31:25 [ERROR] django.security.DisallowedHost (exception): Invalid HTTP_HOST header: '43.203.213.169'. You may need to add '43.203.213.169' to ALLOWED_HOSTS.
Traceback (most recent call last):
  File "/home/ubuntu/Festival/venv/lib/python3.12/site-packages/django/core/handlers/exception.py", line 55, in inner
    response = get_response(request)
               ^^^^^^^^^^^^^^^^^^^^^
  File "/home/ubuntu/Festival/venv/lib/python3.12/site-packages/django/utils/deprecation.py", line 128, in __call__
    response = self.process_request(request)
               ^^^^^^^^^^^^^^^^^^^^^^^^^^^^^
  File "/home/ubuntu/Festival/venv/lib/python3.12/site-packages/django/middleware/common.py", line 48, in process_request
    host = request.get_host()
           ^^^^^^^^^^^^^^^^^^
  File "/home/ubuntu/Festival/venv/lib/python3.12/site-packages/django/http/request.py", line 151, in get_host
    raise DisallowedHost(msg)
django.core.exceptions.DisallowedHost: Invalid HTTP_HOST header: '43.203.213.169'. You may need to add '43.203.213.169' to ALLOWED_HOSTS.
2024-11-19 02:31:25 [WARNING] django.request (log): Bad Request: /
2024-11-19 02:31:25 [ERROR] django.security.DisallowedHost (exception): Invalid HTTP_HOST header: '43.203.213.169'. You may need to add '43.203.213.169' to ALLOWED_HOSTS.
Traceback (most recent call last):
  File "/home/ubuntu/Festival/venv/lib/python3.12/site-packages/django/core/handlers/exception.py", line 55, in inner
    response = get_response(request)
               ^^^^^^^^^^^^^^^^^^^^^
  File "/home/ubuntu/Festival/venv/lib/python3.12/site-packages/django/utils/deprecation.py", line 128, in __call__
    response = self.process_request(request)
               ^^^^^^^^^^^^^^^^^^^^^^^^^^^^^
  File "/home/ubuntu/Festival/venv/lib/python3.12/site-packages/django/middleware/common.py", line 48, in process_request
    host = request.get_host()
           ^^^^^^^^^^^^^^^^^^
  File "/home/ubuntu/Festival/venv/lib/python3.12/site-packages/django/http/request.py", line 151, in get_host
    raise DisallowedHost(msg)
django.core.exceptions.DisallowedHost: Invalid HTTP_HOST header: '43.203.213.169'. You may need to add '43.203.213.169' to ALLOWED_HOSTS.
2024-11-19 02:31:26 [DEBUG] faiss.loader (loader): Environment variable FAISS_OPT_LEVEL is not set, so let's pick the instruction set according to the current CPU
2024-11-19 02:31:26 [INFO] faiss.loader (loader): Loading faiss with AVX2 support.
2024-11-19 02:31:26 [INFO] faiss.loader (loader): Successfully loaded faiss with AVX2 support.
2024-11-19 02:31:27 [DEBUG] pydot (__init__): pydot initializing
2024-11-19 02:31:27 [DEBUG] pydot (__init__): pydot 3.0.2
2024-11-19 02:31:27 [DEBUG] pydot.dot_parser (dot_parser): pydot dot_parser module initializing
2024-11-19 02:31:27 [DEBUG] pydot.core (core): pydot core module initializing
2024-11-19 02:31:27 [ERROR] django.security.DisallowedHost (exception): Invalid HTTP_HOST header: '43.203.213.169'. You may need to add '43.203.213.169' to ALLOWED_HOSTS.
Traceback (most recent call last):
  File "/home/ubuntu/Festival/venv/lib/python3.12/site-packages/django/core/handlers/exception.py", line 55, in inner
    response = get_response(request)
               ^^^^^^^^^^^^^^^^^^^^^
  File "/home/ubuntu/Festival/venv/lib/python3.12/site-packages/django/utils/deprecation.py", line 128, in __call__
    response = self.process_request(request)
               ^^^^^^^^^^^^^^^^^^^^^^^^^^^^^
  File "/home/ubuntu/Festival/venv/lib/python3.12/site-packages/django/middleware/common.py", line 48, in process_request
    host = request.get_host()
           ^^^^^^^^^^^^^^^^^^
  File "/home/ubuntu/Festival/venv/lib/python3.12/site-packages/django/http/request.py", line 151, in get_host
    raise DisallowedHost(msg)
django.core.exceptions.DisallowedHost: Invalid HTTP_HOST header: '43.203.213.169'. You may need to add '43.203.213.169' to ALLOWED_HOSTS.
2024-11-19 02:31:27 [WARNING] django.request (log): Bad Request: /
2024-11-19 02:31:27 [ERROR] django.security.DisallowedHost (exception): Invalid HTTP_HOST header: '43.203.213.169'. You may need to add '43.203.213.169' to ALLOWED_HOSTS.
Traceback (most recent call last):
  File "/home/ubuntu/Festival/venv/lib/python3.12/site-packages/django/core/handlers/exception.py", line 55, in inner
    response = get_response(request)
               ^^^^^^^^^^^^^^^^^^^^^
  File "/home/ubuntu/Festival/venv/lib/python3.12/site-packages/django/utils/deprecation.py", line 128, in __call__
    response = self.process_request(request)
               ^^^^^^^^^^^^^^^^^^^^^^^^^^^^^
  File "/home/ubuntu/Festival/venv/lib/python3.12/site-packages/django/middleware/common.py", line 48, in process_request
    host = request.get_host()
           ^^^^^^^^^^^^^^^^^^
  File "/home/ubuntu/Festival/venv/lib/python3.12/site-packages/django/http/request.py", line 151, in get_host
    raise DisallowedHost(msg)
django.core.exceptions.DisallowedHost: Invalid HTTP_HOST header: '43.203.213.169'. You may need to add '43.203.213.169' to ALLOWED_HOSTS.
2024-11-19 02:31:27 [WARNING] django.request (log): Bad Request: /favicon.ico
2024-11-19 02:31:29 [WARNING] django.request (log): Bad Request: /favicon.ico
2024-11-19 02:34:02 [DEBUG] faiss.loader (loader): Environment variable FAISS_OPT_LEVEL is not set, so let's pick the instruction set according to the current CPU
2024-11-19 02:34:02 [INFO] faiss.loader (loader): Loading faiss with AVX2 support.
2024-11-19 02:34:02 [INFO] faiss.loader (loader): Successfully loaded faiss with AVX2 support.
2024-11-19 02:34:03 [DEBUG] pydot (__init__): pydot initializing
2024-11-19 02:34:03 [DEBUG] pydot (__init__): pydot 3.0.2
2024-11-19 02:34:03 [DEBUG] pydot.dot_parser (dot_parser): pydot dot_parser module initializing
2024-11-19 02:34:03 [DEBUG] pydot.core (core): pydot core module initializing
2024-11-19 02:34:05 [WARNING] django.request (log): Not Found: /
2024-11-19 02:34:05 [WARNING] django.request (log): Not Found: /favicon.ico
2024-11-19 02:34:14 [DEBUG] faiss.loader (loader): Environment variable FAISS_OPT_LEVEL is not set, so let's pick the instruction set according to the current CPU
2024-11-19 02:34:14 [INFO] faiss.loader (loader): Loading faiss with AVX2 support.
2024-11-19 02:34:14 [INFO] faiss.loader (loader): Successfully loaded faiss with AVX2 support.
2024-11-19 02:34:15 [DEBUG] pydot (__init__): pydot initializing
2024-11-19 02:34:15 [DEBUG] pydot (__init__): pydot 3.0.2
2024-11-19 02:34:15 [DEBUG] pydot.dot_parser (dot_parser): pydot dot_parser module initializing
2024-11-19 02:34:15 [DEBUG] pydot.core (core): pydot core module initializing
2024-11-19 02:34:17 [WARNING] django.request (log): Not Found: /api/
2024-11-19 02:51:43 [WARNING] django.request (log): Not Found: /
2024-11-19 03:05:50 [DEBUG] faiss.loader (loader): Environment variable FAISS_OPT_LEVEL is not set, so let's pick the instruction set according to the current CPU
2024-11-19 03:05:50 [INFO] faiss.loader (loader): Loading faiss with AVX2 support.
2024-11-19 03:05:50 [INFO] faiss.loader (loader): Successfully loaded faiss with AVX2 support.
2024-11-19 03:05:51 [DEBUG] pydot (__init__): pydot initializing
2024-11-19 03:05:51 [DEBUG] pydot (__init__): pydot 3.0.2
2024-11-19 03:05:51 [DEBUG] pydot.dot_parser (dot_parser): pydot dot_parser module initializing
2024-11-19 03:05:51 [DEBUG] pydot.core (core): pydot core module initializing
2024-11-19 03:05:53 [WARNING] django.request (log): Not Found: /
2024-11-19 03:09:51 [WARNING] django.request (log): Not Found: /
2024-11-19 03:11:11 [WARNING] django.request (log): Not Found: /
2024-11-19 03:13:41 [WARNING] django.request (log): Not Found: /
2024-11-19 03:13:42 [WARNING] django.request (log): Not Found: /
2024-11-19 03:27:43 [WARNING] django.request (log): Not Found: /api/
2024-11-19 03:37:06 [WARNING] django.request (log): Not Found: /api/
2024-11-19 03:40:03 [INFO] api.views (views): Fetching all festivals.
2024-11-19 03:40:03 [ERROR] django.request (log): Internal Server Error: /api/festivals/
Traceback (most recent call last):
  File "/home/ubuntu/Festival/venv/lib/python3.12/site-packages/django/db/backends/base/base.py", line 279, in ensure_connection
    self.connect()
  File "/home/ubuntu/Festival/venv/lib/python3.12/site-packages/django/utils/asyncio.py", line 26, in inner
    return func(*args, **kwargs)
           ^^^^^^^^^^^^^^^^^^^^^
  File "/home/ubuntu/Festival/venv/lib/python3.12/site-packages/django/db/backends/base/base.py", line 256, in connect
    self.connection = self.get_new_connection(conn_params)
                      ^^^^^^^^^^^^^^^^^^^^^^^^^^^^^^^^^^^^
  File "/home/ubuntu/Festival/venv/lib/python3.12/site-packages/django/utils/asyncio.py", line 26, in inner
    return func(*args, **kwargs)
           ^^^^^^^^^^^^^^^^^^^^^
  File "/home/ubuntu/Festival/venv/lib/python3.12/site-packages/django/db/backends/mysql/base.py", line 256, in get_new_connection
    connection = Database.connect(**conn_params)
                 ^^^^^^^^^^^^^^^^^^^^^^^^^^^^^^^
  File "/home/ubuntu/Festival/venv/lib/python3.12/site-packages/MySQLdb/__init__.py", line 121, in Connect
    return Connection(*args, **kwargs)
           ^^^^^^^^^^^^^^^^^^^^^^^^^^^
  File "/home/ubuntu/Festival/venv/lib/python3.12/site-packages/MySQLdb/connections.py", line 195, in __init__
    super().__init__(*args, **kwargs2)
MySQLdb.OperationalError: (1045, "Access denied for user 'root'@'localhost' (using password: YES)")

The above exception was the direct cause of the following exception:

Traceback (most recent call last):
  File "/home/ubuntu/Festival/venv/lib/python3.12/site-packages/django/core/handlers/exception.py", line 55, in inner
    response = get_response(request)
               ^^^^^^^^^^^^^^^^^^^^^
  File "/home/ubuntu/Festival/venv/lib/python3.12/site-packages/django/core/handlers/base.py", line 197, in _get_response
    response = wrapped_callback(request, *callback_args, **callback_kwargs)
               ^^^^^^^^^^^^^^^^^^^^^^^^^^^^^^^^^^^^^^^^^^^^^^^^^^^^^^^^^^^^
  File "/home/ubuntu/Festival/venv/lib/python3.12/site-packages/django/views/decorators/csrf.py", line 65, in _view_wrapper
    return view_func(request, *args, **kwargs)
           ^^^^^^^^^^^^^^^^^^^^^^^^^^^^^^^^^^^
  File "/home/ubuntu/Festival/venv/lib/python3.12/site-packages/django/views/generic/base.py", line 104, in view
    return self.dispatch(request, *args, **kwargs)
           ^^^^^^^^^^^^^^^^^^^^^^^^^^^^^^^^^^^^^^^
  File "/home/ubuntu/Festival/venv/lib/python3.12/site-packages/rest_framework/views.py", line 509, in dispatch
    response = self.handle_exception(exc)
               ^^^^^^^^^^^^^^^^^^^^^^^^^^
  File "/home/ubuntu/Festival/venv/lib/python3.12/site-packages/rest_framework/views.py", line 469, in handle_exception
    self.raise_uncaught_exception(exc)
  File "/home/ubuntu/Festival/venv/lib/python3.12/site-packages/rest_framework/views.py", line 480, in raise_uncaught_exception
    raise exc
  File "/home/ubuntu/Festival/venv/lib/python3.12/site-packages/rest_framework/views.py", line 506, in dispatch
    response = handler(request, *args, **kwargs)
               ^^^^^^^^^^^^^^^^^^^^^^^^^^^^^^^^^
  File "/home/ubuntu/Festival/venv/lib/python3.12/site-packages/rest_framework/generics.py", line 243, in get
    return self.list(request, *args, **kwargs)
           ^^^^^^^^^^^^^^^^^^^^^^^^^^^^^^^^^^^
  File "/home/ubuntu/Festival/venv/lib/python3.12/site-packages/rest_framework/mixins.py", line 46, in list
    return Response(serializer.data)
                    ^^^^^^^^^^^^^^^
  File "/home/ubuntu/Festival/venv/lib/python3.12/site-packages/rest_framework/serializers.py", line 795, in data
    ret = super().data
          ^^^^^^^^^^^^
  File "/home/ubuntu/Festival/venv/lib/python3.12/site-packages/rest_framework/serializers.py", line 249, in data
    self._data = self.to_representation(self.instance)
                 ^^^^^^^^^^^^^^^^^^^^^^^^^^^^^^^^^^^^^
  File "/home/ubuntu/Festival/venv/lib/python3.12/site-packages/rest_framework/serializers.py", line 713, in to_representation
    return [
           ^
  File "/home/ubuntu/Festival/venv/lib/python3.12/site-packages/django/db/models/query.py", line 400, in __iter__
    self._fetch_all()
  File "/home/ubuntu/Festival/venv/lib/python3.12/site-packages/django/db/models/query.py", line 1928, in _fetch_all
    self._result_cache = list(self._iterable_class(self))
                         ^^^^^^^^^^^^^^^^^^^^^^^^^^^^^^^^
  File "/home/ubuntu/Festival/venv/lib/python3.12/site-packages/django/db/models/query.py", line 91, in __iter__
    results = compiler.execute_sql(
              ^^^^^^^^^^^^^^^^^^^^^
  File "/home/ubuntu/Festival/venv/lib/python3.12/site-packages/django/db/models/sql/compiler.py", line 1572, in execute_sql
    cursor = self.connection.cursor()
             ^^^^^^^^^^^^^^^^^^^^^^^^
  File "/home/ubuntu/Festival/venv/lib/python3.12/site-packages/django/utils/asyncio.py", line 26, in inner
    return func(*args, **kwargs)
           ^^^^^^^^^^^^^^^^^^^^^
  File "/home/ubuntu/Festival/venv/lib/python3.12/site-packages/django/db/backends/base/base.py", line 320, in cursor
    return self._cursor()
           ^^^^^^^^^^^^^^
  File "/home/ubuntu/Festival/venv/lib/python3.12/site-packages/django/db/backends/base/base.py", line 296, in _cursor
    self.ensure_connection()
  File "/home/ubuntu/Festival/venv/lib/python3.12/site-packages/django/utils/asyncio.py", line 26, in inner
    return func(*args, **kwargs)
           ^^^^^^^^^^^^^^^^^^^^^
  File "/home/ubuntu/Festival/venv/lib/python3.12/site-packages/django/db/backends/base/base.py", line 278, in ensure_connection
    with self.wrap_database_errors:
  File "/home/ubuntu/Festival/venv/lib/python3.12/site-packages/django/db/utils.py", line 91, in __exit__
    raise dj_exc_value.with_traceback(traceback) from exc_value
  File "/home/ubuntu/Festival/venv/lib/python3.12/site-packages/django/db/backends/base/base.py", line 279, in ensure_connection
    self.connect()
  File "/home/ubuntu/Festival/venv/lib/python3.12/site-packages/django/utils/asyncio.py", line 26, in inner
    return func(*args, **kwargs)
           ^^^^^^^^^^^^^^^^^^^^^
  File "/home/ubuntu/Festival/venv/lib/python3.12/site-packages/django/db/backends/base/base.py", line 256, in connect
    self.connection = self.get_new_connection(conn_params)
                      ^^^^^^^^^^^^^^^^^^^^^^^^^^^^^^^^^^^^
  File "/home/ubuntu/Festival/venv/lib/python3.12/site-packages/django/utils/asyncio.py", line 26, in inner
    return func(*args, **kwargs)
           ^^^^^^^^^^^^^^^^^^^^^
  File "/home/ubuntu/Festival/venv/lib/python3.12/site-packages/django/db/backends/mysql/base.py", line 256, in get_new_connection
    connection = Database.connect(**conn_params)
                 ^^^^^^^^^^^^^^^^^^^^^^^^^^^^^^^
  File "/home/ubuntu/Festival/venv/lib/python3.12/site-packages/MySQLdb/__init__.py", line 121, in Connect
    return Connection(*args, **kwargs)
           ^^^^^^^^^^^^^^^^^^^^^^^^^^^
  File "/home/ubuntu/Festival/venv/lib/python3.12/site-packages/MySQLdb/connections.py", line 195, in __init__
    super().__init__(*args, **kwargs2)
django.db.utils.OperationalError: (1045, "Access denied for user 'root'@'localhost' (using password: YES)")
2024-11-19 03:41:17 [INFO] api.views (views): Fetching all festivals.
2024-11-19 03:41:17 [ERROR] django.request (log): Internal Server Error: /api/festivals/
Traceback (most recent call last):
  File "/home/ubuntu/Festival/venv/lib/python3.12/site-packages/django/db/backends/base/base.py", line 279, in ensure_connection
    self.connect()
  File "/home/ubuntu/Festival/venv/lib/python3.12/site-packages/django/utils/asyncio.py", line 26, in inner
    return func(*args, **kwargs)
           ^^^^^^^^^^^^^^^^^^^^^
  File "/home/ubuntu/Festival/venv/lib/python3.12/site-packages/django/db/backends/base/base.py", line 256, in connect
    self.connection = self.get_new_connection(conn_params)
                      ^^^^^^^^^^^^^^^^^^^^^^^^^^^^^^^^^^^^
  File "/home/ubuntu/Festival/venv/lib/python3.12/site-packages/django/utils/asyncio.py", line 26, in inner
    return func(*args, **kwargs)
           ^^^^^^^^^^^^^^^^^^^^^
  File "/home/ubuntu/Festival/venv/lib/python3.12/site-packages/django/db/backends/mysql/base.py", line 256, in get_new_connection
    connection = Database.connect(**conn_params)
                 ^^^^^^^^^^^^^^^^^^^^^^^^^^^^^^^
  File "/home/ubuntu/Festival/venv/lib/python3.12/site-packages/MySQLdb/__init__.py", line 121, in Connect
    return Connection(*args, **kwargs)
           ^^^^^^^^^^^^^^^^^^^^^^^^^^^
  File "/home/ubuntu/Festival/venv/lib/python3.12/site-packages/MySQLdb/connections.py", line 195, in __init__
    super().__init__(*args, **kwargs2)
MySQLdb.OperationalError: (1045, "Access denied for user 'root'@'localhost' (using password: YES)")

The above exception was the direct cause of the following exception:

Traceback (most recent call last):
  File "/home/ubuntu/Festival/venv/lib/python3.12/site-packages/django/core/handlers/exception.py", line 55, in inner
    response = get_response(request)
               ^^^^^^^^^^^^^^^^^^^^^
  File "/home/ubuntu/Festival/venv/lib/python3.12/site-packages/django/core/handlers/base.py", line 197, in _get_response
    response = wrapped_callback(request, *callback_args, **callback_kwargs)
               ^^^^^^^^^^^^^^^^^^^^^^^^^^^^^^^^^^^^^^^^^^^^^^^^^^^^^^^^^^^^
  File "/home/ubuntu/Festival/venv/lib/python3.12/site-packages/django/views/decorators/csrf.py", line 65, in _view_wrapper
    return view_func(request, *args, **kwargs)
           ^^^^^^^^^^^^^^^^^^^^^^^^^^^^^^^^^^^
  File "/home/ubuntu/Festival/venv/lib/python3.12/site-packages/django/views/generic/base.py", line 104, in view
    return self.dispatch(request, *args, **kwargs)
           ^^^^^^^^^^^^^^^^^^^^^^^^^^^^^^^^^^^^^^^
  File "/home/ubuntu/Festival/venv/lib/python3.12/site-packages/rest_framework/views.py", line 509, in dispatch
    response = self.handle_exception(exc)
               ^^^^^^^^^^^^^^^^^^^^^^^^^^
  File "/home/ubuntu/Festival/venv/lib/python3.12/site-packages/rest_framework/views.py", line 469, in handle_exception
    self.raise_uncaught_exception(exc)
  File "/home/ubuntu/Festival/venv/lib/python3.12/site-packages/rest_framework/views.py", line 480, in raise_uncaught_exception
    raise exc
  File "/home/ubuntu/Festival/venv/lib/python3.12/site-packages/rest_framework/views.py", line 506, in dispatch
    response = handler(request, *args, **kwargs)
               ^^^^^^^^^^^^^^^^^^^^^^^^^^^^^^^^^
  File "/home/ubuntu/Festival/venv/lib/python3.12/site-packages/rest_framework/generics.py", line 243, in get
    return self.list(request, *args, **kwargs)
           ^^^^^^^^^^^^^^^^^^^^^^^^^^^^^^^^^^^
  File "/home/ubuntu/Festival/venv/lib/python3.12/site-packages/rest_framework/mixins.py", line 46, in list
    return Response(serializer.data)
                    ^^^^^^^^^^^^^^^
  File "/home/ubuntu/Festival/venv/lib/python3.12/site-packages/rest_framework/serializers.py", line 795, in data
    ret = super().data
          ^^^^^^^^^^^^
  File "/home/ubuntu/Festival/venv/lib/python3.12/site-packages/rest_framework/serializers.py", line 249, in data
    self._data = self.to_representation(self.instance)
                 ^^^^^^^^^^^^^^^^^^^^^^^^^^^^^^^^^^^^^
  File "/home/ubuntu/Festival/venv/lib/python3.12/site-packages/rest_framework/serializers.py", line 713, in to_representation
    return [
           ^
  File "/home/ubuntu/Festival/venv/lib/python3.12/site-packages/django/db/models/query.py", line 400, in __iter__
    self._fetch_all()
  File "/home/ubuntu/Festival/venv/lib/python3.12/site-packages/django/db/models/query.py", line 1928, in _fetch_all
    self._result_cache = list(self._iterable_class(self))
                         ^^^^^^^^^^^^^^^^^^^^^^^^^^^^^^^^
  File "/home/ubuntu/Festival/venv/lib/python3.12/site-packages/django/db/models/query.py", line 91, in __iter__
    results = compiler.execute_sql(
              ^^^^^^^^^^^^^^^^^^^^^
  File "/home/ubuntu/Festival/venv/lib/python3.12/site-packages/django/db/models/sql/compiler.py", line 1572, in execute_sql
    cursor = self.connection.cursor()
             ^^^^^^^^^^^^^^^^^^^^^^^^
  File "/home/ubuntu/Festival/venv/lib/python3.12/site-packages/django/utils/asyncio.py", line 26, in inner
    return func(*args, **kwargs)
           ^^^^^^^^^^^^^^^^^^^^^
  File "/home/ubuntu/Festival/venv/lib/python3.12/site-packages/django/db/backends/base/base.py", line 320, in cursor
    return self._cursor()
           ^^^^^^^^^^^^^^
  File "/home/ubuntu/Festival/venv/lib/python3.12/site-packages/django/db/backends/base/base.py", line 296, in _cursor
    self.ensure_connection()
  File "/home/ubuntu/Festival/venv/lib/python3.12/site-packages/django/utils/asyncio.py", line 26, in inner
    return func(*args, **kwargs)
           ^^^^^^^^^^^^^^^^^^^^^
  File "/home/ubuntu/Festival/venv/lib/python3.12/site-packages/django/db/backends/base/base.py", line 278, in ensure_connection
    with self.wrap_database_errors:
  File "/home/ubuntu/Festival/venv/lib/python3.12/site-packages/django/db/utils.py", line 91, in __exit__
    raise dj_exc_value.with_traceback(traceback) from exc_value
  File "/home/ubuntu/Festival/venv/lib/python3.12/site-packages/django/db/backends/base/base.py", line 279, in ensure_connection
    self.connect()
  File "/home/ubuntu/Festival/venv/lib/python3.12/site-packages/django/utils/asyncio.py", line 26, in inner
    return func(*args, **kwargs)
           ^^^^^^^^^^^^^^^^^^^^^
  File "/home/ubuntu/Festival/venv/lib/python3.12/site-packages/django/db/backends/base/base.py", line 256, in connect
    self.connection = self.get_new_connection(conn_params)
                      ^^^^^^^^^^^^^^^^^^^^^^^^^^^^^^^^^^^^
  File "/home/ubuntu/Festival/venv/lib/python3.12/site-packages/django/utils/asyncio.py", line 26, in inner
    return func(*args, **kwargs)
           ^^^^^^^^^^^^^^^^^^^^^
  File "/home/ubuntu/Festival/venv/lib/python3.12/site-packages/django/db/backends/mysql/base.py", line 256, in get_new_connection
    connection = Database.connect(**conn_params)
                 ^^^^^^^^^^^^^^^^^^^^^^^^^^^^^^^
  File "/home/ubuntu/Festival/venv/lib/python3.12/site-packages/MySQLdb/__init__.py", line 121, in Connect
    return Connection(*args, **kwargs)
           ^^^^^^^^^^^^^^^^^^^^^^^^^^^
  File "/home/ubuntu/Festival/venv/lib/python3.12/site-packages/MySQLdb/connections.py", line 195, in __init__
    super().__init__(*args, **kwargs2)
django.db.utils.OperationalError: (1045, "Access denied for user 'root'@'localhost' (using password: YES)")
2024-11-19 03:41:20 [INFO] api.views (views): Fetching all festivals.
2024-11-19 03:41:20 [ERROR] django.request (log): Internal Server Error: /api/festivals/
Traceback (most recent call last):
  File "/home/ubuntu/Festival/venv/lib/python3.12/site-packages/django/db/backends/base/base.py", line 279, in ensure_connection
    self.connect()
  File "/home/ubuntu/Festival/venv/lib/python3.12/site-packages/django/utils/asyncio.py", line 26, in inner
    return func(*args, **kwargs)
           ^^^^^^^^^^^^^^^^^^^^^
  File "/home/ubuntu/Festival/venv/lib/python3.12/site-packages/django/db/backends/base/base.py", line 256, in connect
    self.connection = self.get_new_connection(conn_params)
                      ^^^^^^^^^^^^^^^^^^^^^^^^^^^^^^^^^^^^
  File "/home/ubuntu/Festival/venv/lib/python3.12/site-packages/django/utils/asyncio.py", line 26, in inner
    return func(*args, **kwargs)
           ^^^^^^^^^^^^^^^^^^^^^
  File "/home/ubuntu/Festival/venv/lib/python3.12/site-packages/django/db/backends/mysql/base.py", line 256, in get_new_connection
    connection = Database.connect(**conn_params)
                 ^^^^^^^^^^^^^^^^^^^^^^^^^^^^^^^
  File "/home/ubuntu/Festival/venv/lib/python3.12/site-packages/MySQLdb/__init__.py", line 121, in Connect
    return Connection(*args, **kwargs)
           ^^^^^^^^^^^^^^^^^^^^^^^^^^^
  File "/home/ubuntu/Festival/venv/lib/python3.12/site-packages/MySQLdb/connections.py", line 195, in __init__
    super().__init__(*args, **kwargs2)
MySQLdb.OperationalError: (1045, "Access denied for user 'root'@'localhost' (using password: YES)")

The above exception was the direct cause of the following exception:

Traceback (most recent call last):
  File "/home/ubuntu/Festival/venv/lib/python3.12/site-packages/django/core/handlers/exception.py", line 55, in inner
    response = get_response(request)
               ^^^^^^^^^^^^^^^^^^^^^
  File "/home/ubuntu/Festival/venv/lib/python3.12/site-packages/django/core/handlers/base.py", line 197, in _get_response
    response = wrapped_callback(request, *callback_args, **callback_kwargs)
               ^^^^^^^^^^^^^^^^^^^^^^^^^^^^^^^^^^^^^^^^^^^^^^^^^^^^^^^^^^^^
  File "/home/ubuntu/Festival/venv/lib/python3.12/site-packages/django/views/decorators/csrf.py", line 65, in _view_wrapper
    return view_func(request, *args, **kwargs)
           ^^^^^^^^^^^^^^^^^^^^^^^^^^^^^^^^^^^
  File "/home/ubuntu/Festival/venv/lib/python3.12/site-packages/django/views/generic/base.py", line 104, in view
    return self.dispatch(request, *args, **kwargs)
           ^^^^^^^^^^^^^^^^^^^^^^^^^^^^^^^^^^^^^^^
  File "/home/ubuntu/Festival/venv/lib/python3.12/site-packages/rest_framework/views.py", line 509, in dispatch
    response = self.handle_exception(exc)
               ^^^^^^^^^^^^^^^^^^^^^^^^^^
  File "/home/ubuntu/Festival/venv/lib/python3.12/site-packages/rest_framework/views.py", line 469, in handle_exception
    self.raise_uncaught_exception(exc)
  File "/home/ubuntu/Festival/venv/lib/python3.12/site-packages/rest_framework/views.py", line 480, in raise_uncaught_exception
    raise exc
  File "/home/ubuntu/Festival/venv/lib/python3.12/site-packages/rest_framework/views.py", line 506, in dispatch
    response = handler(request, *args, **kwargs)
               ^^^^^^^^^^^^^^^^^^^^^^^^^^^^^^^^^
  File "/home/ubuntu/Festival/venv/lib/python3.12/site-packages/rest_framework/generics.py", line 243, in get
    return self.list(request, *args, **kwargs)
           ^^^^^^^^^^^^^^^^^^^^^^^^^^^^^^^^^^^
  File "/home/ubuntu/Festival/venv/lib/python3.12/site-packages/rest_framework/mixins.py", line 46, in list
    return Response(serializer.data)
                    ^^^^^^^^^^^^^^^
  File "/home/ubuntu/Festival/venv/lib/python3.12/site-packages/rest_framework/serializers.py", line 795, in data
    ret = super().data
          ^^^^^^^^^^^^
  File "/home/ubuntu/Festival/venv/lib/python3.12/site-packages/rest_framework/serializers.py", line 249, in data
    self._data = self.to_representation(self.instance)
                 ^^^^^^^^^^^^^^^^^^^^^^^^^^^^^^^^^^^^^
  File "/home/ubuntu/Festival/venv/lib/python3.12/site-packages/rest_framework/serializers.py", line 713, in to_representation
    return [
           ^
  File "/home/ubuntu/Festival/venv/lib/python3.12/site-packages/django/db/models/query.py", line 400, in __iter__
    self._fetch_all()
  File "/home/ubuntu/Festival/venv/lib/python3.12/site-packages/django/db/models/query.py", line 1928, in _fetch_all
    self._result_cache = list(self._iterable_class(self))
                         ^^^^^^^^^^^^^^^^^^^^^^^^^^^^^^^^
  File "/home/ubuntu/Festival/venv/lib/python3.12/site-packages/django/db/models/query.py", line 91, in __iter__
    results = compiler.execute_sql(
              ^^^^^^^^^^^^^^^^^^^^^
  File "/home/ubuntu/Festival/venv/lib/python3.12/site-packages/django/db/models/sql/compiler.py", line 1572, in execute_sql
    cursor = self.connection.cursor()
             ^^^^^^^^^^^^^^^^^^^^^^^^
  File "/home/ubuntu/Festival/venv/lib/python3.12/site-packages/django/utils/asyncio.py", line 26, in inner
    return func(*args, **kwargs)
           ^^^^^^^^^^^^^^^^^^^^^
  File "/home/ubuntu/Festival/venv/lib/python3.12/site-packages/django/db/backends/base/base.py", line 320, in cursor
    return self._cursor()
           ^^^^^^^^^^^^^^
  File "/home/ubuntu/Festival/venv/lib/python3.12/site-packages/django/db/backends/base/base.py", line 296, in _cursor
    self.ensure_connection()
  File "/home/ubuntu/Festival/venv/lib/python3.12/site-packages/django/utils/asyncio.py", line 26, in inner
    return func(*args, **kwargs)
           ^^^^^^^^^^^^^^^^^^^^^
  File "/home/ubuntu/Festival/venv/lib/python3.12/site-packages/django/db/backends/base/base.py", line 278, in ensure_connection
    with self.wrap_database_errors:
  File "/home/ubuntu/Festival/venv/lib/python3.12/site-packages/django/db/utils.py", line 91, in __exit__
    raise dj_exc_value.with_traceback(traceback) from exc_value
  File "/home/ubuntu/Festival/venv/lib/python3.12/site-packages/django/db/backends/base/base.py", line 279, in ensure_connection
    self.connect()
  File "/home/ubuntu/Festival/venv/lib/python3.12/site-packages/django/utils/asyncio.py", line 26, in inner
    return func(*args, **kwargs)
           ^^^^^^^^^^^^^^^^^^^^^
  File "/home/ubuntu/Festival/venv/lib/python3.12/site-packages/django/db/backends/base/base.py", line 256, in connect
    self.connection = self.get_new_connection(conn_params)
                      ^^^^^^^^^^^^^^^^^^^^^^^^^^^^^^^^^^^^
  File "/home/ubuntu/Festival/venv/lib/python3.12/site-packages/django/utils/asyncio.py", line 26, in inner
    return func(*args, **kwargs)
           ^^^^^^^^^^^^^^^^^^^^^
  File "/home/ubuntu/Festival/venv/lib/python3.12/site-packages/django/db/backends/mysql/base.py", line 256, in get_new_connection
    connection = Database.connect(**conn_params)
                 ^^^^^^^^^^^^^^^^^^^^^^^^^^^^^^^
  File "/home/ubuntu/Festival/venv/lib/python3.12/site-packages/MySQLdb/__init__.py", line 121, in Connect
    return Connection(*args, **kwargs)
           ^^^^^^^^^^^^^^^^^^^^^^^^^^^
  File "/home/ubuntu/Festival/venv/lib/python3.12/site-packages/MySQLdb/connections.py", line 195, in __init__
    super().__init__(*args, **kwargs2)
django.db.utils.OperationalError: (1045, "Access denied for user 'root'@'localhost' (using password: YES)")
2024-11-19 03:41:21 [INFO] api.views (views): Fetching all festivals.
2024-11-19 03:41:21 [ERROR] django.request (log): Internal Server Error: /api/festivals/
Traceback (most recent call last):
  File "/home/ubuntu/Festival/venv/lib/python3.12/site-packages/django/db/backends/base/base.py", line 279, in ensure_connection
    self.connect()
  File "/home/ubuntu/Festival/venv/lib/python3.12/site-packages/django/utils/asyncio.py", line 26, in inner
    return func(*args, **kwargs)
           ^^^^^^^^^^^^^^^^^^^^^
  File "/home/ubuntu/Festival/venv/lib/python3.12/site-packages/django/db/backends/base/base.py", line 256, in connect
    self.connection = self.get_new_connection(conn_params)
                      ^^^^^^^^^^^^^^^^^^^^^^^^^^^^^^^^^^^^
  File "/home/ubuntu/Festival/venv/lib/python3.12/site-packages/django/utils/asyncio.py", line 26, in inner
    return func(*args, **kwargs)
           ^^^^^^^^^^^^^^^^^^^^^
  File "/home/ubuntu/Festival/venv/lib/python3.12/site-packages/django/db/backends/mysql/base.py", line 256, in get_new_connection
    connection = Database.connect(**conn_params)
                 ^^^^^^^^^^^^^^^^^^^^^^^^^^^^^^^
  File "/home/ubuntu/Festival/venv/lib/python3.12/site-packages/MySQLdb/__init__.py", line 121, in Connect
    return Connection(*args, **kwargs)
           ^^^^^^^^^^^^^^^^^^^^^^^^^^^
  File "/home/ubuntu/Festival/venv/lib/python3.12/site-packages/MySQLdb/connections.py", line 195, in __init__
    super().__init__(*args, **kwargs2)
MySQLdb.OperationalError: (1045, "Access denied for user 'root'@'localhost' (using password: YES)")

The above exception was the direct cause of the following exception:

Traceback (most recent call last):
  File "/home/ubuntu/Festival/venv/lib/python3.12/site-packages/django/core/handlers/exception.py", line 55, in inner
    response = get_response(request)
               ^^^^^^^^^^^^^^^^^^^^^
  File "/home/ubuntu/Festival/venv/lib/python3.12/site-packages/django/core/handlers/base.py", line 197, in _get_response
    response = wrapped_callback(request, *callback_args, **callback_kwargs)
               ^^^^^^^^^^^^^^^^^^^^^^^^^^^^^^^^^^^^^^^^^^^^^^^^^^^^^^^^^^^^
  File "/home/ubuntu/Festival/venv/lib/python3.12/site-packages/django/views/decorators/csrf.py", line 65, in _view_wrapper
    return view_func(request, *args, **kwargs)
           ^^^^^^^^^^^^^^^^^^^^^^^^^^^^^^^^^^^
  File "/home/ubuntu/Festival/venv/lib/python3.12/site-packages/django/views/generic/base.py", line 104, in view
    return self.dispatch(request, *args, **kwargs)
           ^^^^^^^^^^^^^^^^^^^^^^^^^^^^^^^^^^^^^^^
  File "/home/ubuntu/Festival/venv/lib/python3.12/site-packages/rest_framework/views.py", line 509, in dispatch
    response = self.handle_exception(exc)
               ^^^^^^^^^^^^^^^^^^^^^^^^^^
  File "/home/ubuntu/Festival/venv/lib/python3.12/site-packages/rest_framework/views.py", line 469, in handle_exception
    self.raise_uncaught_exception(exc)
  File "/home/ubuntu/Festival/venv/lib/python3.12/site-packages/rest_framework/views.py", line 480, in raise_uncaught_exception
    raise exc
  File "/home/ubuntu/Festival/venv/lib/python3.12/site-packages/rest_framework/views.py", line 506, in dispatch
    response = handler(request, *args, **kwargs)
               ^^^^^^^^^^^^^^^^^^^^^^^^^^^^^^^^^
  File "/home/ubuntu/Festival/venv/lib/python3.12/site-packages/rest_framework/generics.py", line 243, in get
    return self.list(request, *args, **kwargs)
           ^^^^^^^^^^^^^^^^^^^^^^^^^^^^^^^^^^^
  File "/home/ubuntu/Festival/venv/lib/python3.12/site-packages/rest_framework/mixins.py", line 46, in list
    return Response(serializer.data)
                    ^^^^^^^^^^^^^^^
  File "/home/ubuntu/Festival/venv/lib/python3.12/site-packages/rest_framework/serializers.py", line 795, in data
    ret = super().data
          ^^^^^^^^^^^^
  File "/home/ubuntu/Festival/venv/lib/python3.12/site-packages/rest_framework/serializers.py", line 249, in data
    self._data = self.to_representation(self.instance)
                 ^^^^^^^^^^^^^^^^^^^^^^^^^^^^^^^^^^^^^
  File "/home/ubuntu/Festival/venv/lib/python3.12/site-packages/rest_framework/serializers.py", line 713, in to_representation
    return [
           ^
  File "/home/ubuntu/Festival/venv/lib/python3.12/site-packages/django/db/models/query.py", line 400, in __iter__
    self._fetch_all()
  File "/home/ubuntu/Festival/venv/lib/python3.12/site-packages/django/db/models/query.py", line 1928, in _fetch_all
    self._result_cache = list(self._iterable_class(self))
                         ^^^^^^^^^^^^^^^^^^^^^^^^^^^^^^^^
  File "/home/ubuntu/Festival/venv/lib/python3.12/site-packages/django/db/models/query.py", line 91, in __iter__
    results = compiler.execute_sql(
              ^^^^^^^^^^^^^^^^^^^^^
  File "/home/ubuntu/Festival/venv/lib/python3.12/site-packages/django/db/models/sql/compiler.py", line 1572, in execute_sql
    cursor = self.connection.cursor()
             ^^^^^^^^^^^^^^^^^^^^^^^^
  File "/home/ubuntu/Festival/venv/lib/python3.12/site-packages/django/utils/asyncio.py", line 26, in inner
    return func(*args, **kwargs)
           ^^^^^^^^^^^^^^^^^^^^^
  File "/home/ubuntu/Festival/venv/lib/python3.12/site-packages/django/db/backends/base/base.py", line 320, in cursor
    return self._cursor()
           ^^^^^^^^^^^^^^
  File "/home/ubuntu/Festival/venv/lib/python3.12/site-packages/django/db/backends/base/base.py", line 296, in _cursor
    self.ensure_connection()
  File "/home/ubuntu/Festival/venv/lib/python3.12/site-packages/django/utils/asyncio.py", line 26, in inner
    return func(*args, **kwargs)
           ^^^^^^^^^^^^^^^^^^^^^
  File "/home/ubuntu/Festival/venv/lib/python3.12/site-packages/django/db/backends/base/base.py", line 278, in ensure_connection
    with self.wrap_database_errors:
  File "/home/ubuntu/Festival/venv/lib/python3.12/site-packages/django/db/utils.py", line 91, in __exit__
    raise dj_exc_value.with_traceback(traceback) from exc_value
  File "/home/ubuntu/Festival/venv/lib/python3.12/site-packages/django/db/backends/base/base.py", line 279, in ensure_connection
    self.connect()
  File "/home/ubuntu/Festival/venv/lib/python3.12/site-packages/django/utils/asyncio.py", line 26, in inner
    return func(*args, **kwargs)
           ^^^^^^^^^^^^^^^^^^^^^
  File "/home/ubuntu/Festival/venv/lib/python3.12/site-packages/django/db/backends/base/base.py", line 256, in connect
    self.connection = self.get_new_connection(conn_params)
                      ^^^^^^^^^^^^^^^^^^^^^^^^^^^^^^^^^^^^
  File "/home/ubuntu/Festival/venv/lib/python3.12/site-packages/django/utils/asyncio.py", line 26, in inner
    return func(*args, **kwargs)
           ^^^^^^^^^^^^^^^^^^^^^
  File "/home/ubuntu/Festival/venv/lib/python3.12/site-packages/django/db/backends/mysql/base.py", line 256, in get_new_connection
    connection = Database.connect(**conn_params)
                 ^^^^^^^^^^^^^^^^^^^^^^^^^^^^^^^
  File "/home/ubuntu/Festival/venv/lib/python3.12/site-packages/MySQLdb/__init__.py", line 121, in Connect
    return Connection(*args, **kwargs)
           ^^^^^^^^^^^^^^^^^^^^^^^^^^^
  File "/home/ubuntu/Festival/venv/lib/python3.12/site-packages/MySQLdb/connections.py", line 195, in __init__
    super().__init__(*args, **kwargs2)
django.db.utils.OperationalError: (1045, "Access denied for user 'root'@'localhost' (using password: YES)")
2024-11-19 03:41:22 [INFO] api.views (views): Fetching all festivals.
2024-11-19 03:41:22 [ERROR] django.request (log): Internal Server Error: /api/festivals/
Traceback (most recent call last):
  File "/home/ubuntu/Festival/venv/lib/python3.12/site-packages/django/db/backends/base/base.py", line 279, in ensure_connection
    self.connect()
  File "/home/ubuntu/Festival/venv/lib/python3.12/site-packages/django/utils/asyncio.py", line 26, in inner
    return func(*args, **kwargs)
           ^^^^^^^^^^^^^^^^^^^^^
  File "/home/ubuntu/Festival/venv/lib/python3.12/site-packages/django/db/backends/base/base.py", line 256, in connect
    self.connection = self.get_new_connection(conn_params)
                      ^^^^^^^^^^^^^^^^^^^^^^^^^^^^^^^^^^^^
  File "/home/ubuntu/Festival/venv/lib/python3.12/site-packages/django/utils/asyncio.py", line 26, in inner
    return func(*args, **kwargs)
           ^^^^^^^^^^^^^^^^^^^^^
  File "/home/ubuntu/Festival/venv/lib/python3.12/site-packages/django/db/backends/mysql/base.py", line 256, in get_new_connection
    connection = Database.connect(**conn_params)
                 ^^^^^^^^^^^^^^^^^^^^^^^^^^^^^^^
  File "/home/ubuntu/Festival/venv/lib/python3.12/site-packages/MySQLdb/__init__.py", line 121, in Connect
    return Connection(*args, **kwargs)
           ^^^^^^^^^^^^^^^^^^^^^^^^^^^
  File "/home/ubuntu/Festival/venv/lib/python3.12/site-packages/MySQLdb/connections.py", line 195, in __init__
    super().__init__(*args, **kwargs2)
MySQLdb.OperationalError: (1045, "Access denied for user 'root'@'localhost' (using password: YES)")

The above exception was the direct cause of the following exception:

Traceback (most recent call last):
  File "/home/ubuntu/Festival/venv/lib/python3.12/site-packages/django/core/handlers/exception.py", line 55, in inner
    response = get_response(request)
               ^^^^^^^^^^^^^^^^^^^^^
  File "/home/ubuntu/Festival/venv/lib/python3.12/site-packages/django/core/handlers/base.py", line 197, in _get_response
    response = wrapped_callback(request, *callback_args, **callback_kwargs)
               ^^^^^^^^^^^^^^^^^^^^^^^^^^^^^^^^^^^^^^^^^^^^^^^^^^^^^^^^^^^^
  File "/home/ubuntu/Festival/venv/lib/python3.12/site-packages/django/views/decorators/csrf.py", line 65, in _view_wrapper
    return view_func(request, *args, **kwargs)
           ^^^^^^^^^^^^^^^^^^^^^^^^^^^^^^^^^^^
  File "/home/ubuntu/Festival/venv/lib/python3.12/site-packages/django/views/generic/base.py", line 104, in view
    return self.dispatch(request, *args, **kwargs)
           ^^^^^^^^^^^^^^^^^^^^^^^^^^^^^^^^^^^^^^^
  File "/home/ubuntu/Festival/venv/lib/python3.12/site-packages/rest_framework/views.py", line 509, in dispatch
    response = self.handle_exception(exc)
               ^^^^^^^^^^^^^^^^^^^^^^^^^^
  File "/home/ubuntu/Festival/venv/lib/python3.12/site-packages/rest_framework/views.py", line 469, in handle_exception
    self.raise_uncaught_exception(exc)
  File "/home/ubuntu/Festival/venv/lib/python3.12/site-packages/rest_framework/views.py", line 480, in raise_uncaught_exception
    raise exc
  File "/home/ubuntu/Festival/venv/lib/python3.12/site-packages/rest_framework/views.py", line 506, in dispatch
    response = handler(request, *args, **kwargs)
               ^^^^^^^^^^^^^^^^^^^^^^^^^^^^^^^^^
  File "/home/ubuntu/Festival/venv/lib/python3.12/site-packages/rest_framework/generics.py", line 243, in get
    return self.list(request, *args, **kwargs)
           ^^^^^^^^^^^^^^^^^^^^^^^^^^^^^^^^^^^
  File "/home/ubuntu/Festival/venv/lib/python3.12/site-packages/rest_framework/mixins.py", line 46, in list
    return Response(serializer.data)
                    ^^^^^^^^^^^^^^^
  File "/home/ubuntu/Festival/venv/lib/python3.12/site-packages/rest_framework/serializers.py", line 795, in data
    ret = super().data
          ^^^^^^^^^^^^
  File "/home/ubuntu/Festival/venv/lib/python3.12/site-packages/rest_framework/serializers.py", line 249, in data
    self._data = self.to_representation(self.instance)
                 ^^^^^^^^^^^^^^^^^^^^^^^^^^^^^^^^^^^^^
  File "/home/ubuntu/Festival/venv/lib/python3.12/site-packages/rest_framework/serializers.py", line 713, in to_representation
    return [
           ^
  File "/home/ubuntu/Festival/venv/lib/python3.12/site-packages/django/db/models/query.py", line 400, in __iter__
    self._fetch_all()
  File "/home/ubuntu/Festival/venv/lib/python3.12/site-packages/django/db/models/query.py", line 1928, in _fetch_all
    self._result_cache = list(self._iterable_class(self))
                         ^^^^^^^^^^^^^^^^^^^^^^^^^^^^^^^^
  File "/home/ubuntu/Festival/venv/lib/python3.12/site-packages/django/db/models/query.py", line 91, in __iter__
    results = compiler.execute_sql(
              ^^^^^^^^^^^^^^^^^^^^^
  File "/home/ubuntu/Festival/venv/lib/python3.12/site-packages/django/db/models/sql/compiler.py", line 1572, in execute_sql
    cursor = self.connection.cursor()
             ^^^^^^^^^^^^^^^^^^^^^^^^
  File "/home/ubuntu/Festival/venv/lib/python3.12/site-packages/django/utils/asyncio.py", line 26, in inner
    return func(*args, **kwargs)
           ^^^^^^^^^^^^^^^^^^^^^
  File "/home/ubuntu/Festival/venv/lib/python3.12/site-packages/django/db/backends/base/base.py", line 320, in cursor
    return self._cursor()
           ^^^^^^^^^^^^^^
  File "/home/ubuntu/Festival/venv/lib/python3.12/site-packages/django/db/backends/base/base.py", line 296, in _cursor
    self.ensure_connection()
  File "/home/ubuntu/Festival/venv/lib/python3.12/site-packages/django/utils/asyncio.py", line 26, in inner
    return func(*args, **kwargs)
           ^^^^^^^^^^^^^^^^^^^^^
  File "/home/ubuntu/Festival/venv/lib/python3.12/site-packages/django/db/backends/base/base.py", line 278, in ensure_connection
    with self.wrap_database_errors:
  File "/home/ubuntu/Festival/venv/lib/python3.12/site-packages/django/db/utils.py", line 91, in __exit__
    raise dj_exc_value.with_traceback(traceback) from exc_value
  File "/home/ubuntu/Festival/venv/lib/python3.12/site-packages/django/db/backends/base/base.py", line 279, in ensure_connection
    self.connect()
  File "/home/ubuntu/Festival/venv/lib/python3.12/site-packages/django/utils/asyncio.py", line 26, in inner
    return func(*args, **kwargs)
           ^^^^^^^^^^^^^^^^^^^^^
  File "/home/ubuntu/Festival/venv/lib/python3.12/site-packages/django/db/backends/base/base.py", line 256, in connect
    self.connection = self.get_new_connection(conn_params)
                      ^^^^^^^^^^^^^^^^^^^^^^^^^^^^^^^^^^^^
  File "/home/ubuntu/Festival/venv/lib/python3.12/site-packages/django/utils/asyncio.py", line 26, in inner
    return func(*args, **kwargs)
           ^^^^^^^^^^^^^^^^^^^^^
  File "/home/ubuntu/Festival/venv/lib/python3.12/site-packages/django/db/backends/mysql/base.py", line 256, in get_new_connection
    connection = Database.connect(**conn_params)
                 ^^^^^^^^^^^^^^^^^^^^^^^^^^^^^^^
  File "/home/ubuntu/Festival/venv/lib/python3.12/site-packages/MySQLdb/__init__.py", line 121, in Connect
    return Connection(*args, **kwargs)
           ^^^^^^^^^^^^^^^^^^^^^^^^^^^
  File "/home/ubuntu/Festival/venv/lib/python3.12/site-packages/MySQLdb/connections.py", line 195, in __init__
    super().__init__(*args, **kwargs2)
django.db.utils.OperationalError: (1045, "Access denied for user 'root'@'localhost' (using password: YES)")
2024-11-19 03:41:23 [INFO] api.views (views): Fetching all festivals.
2024-11-19 03:41:23 [ERROR] django.request (log): Internal Server Error: /api/festivals/
Traceback (most recent call last):
  File "/home/ubuntu/Festival/venv/lib/python3.12/site-packages/django/db/backends/base/base.py", line 279, in ensure_connection
    self.connect()
  File "/home/ubuntu/Festival/venv/lib/python3.12/site-packages/django/utils/asyncio.py", line 26, in inner
    return func(*args, **kwargs)
           ^^^^^^^^^^^^^^^^^^^^^
  File "/home/ubuntu/Festival/venv/lib/python3.12/site-packages/django/db/backends/base/base.py", line 256, in connect
    self.connection = self.get_new_connection(conn_params)
                      ^^^^^^^^^^^^^^^^^^^^^^^^^^^^^^^^^^^^
  File "/home/ubuntu/Festival/venv/lib/python3.12/site-packages/django/utils/asyncio.py", line 26, in inner
    return func(*args, **kwargs)
           ^^^^^^^^^^^^^^^^^^^^^
  File "/home/ubuntu/Festival/venv/lib/python3.12/site-packages/django/db/backends/mysql/base.py", line 256, in get_new_connection
    connection = Database.connect(**conn_params)
                 ^^^^^^^^^^^^^^^^^^^^^^^^^^^^^^^
  File "/home/ubuntu/Festival/venv/lib/python3.12/site-packages/MySQLdb/__init__.py", line 121, in Connect
    return Connection(*args, **kwargs)
           ^^^^^^^^^^^^^^^^^^^^^^^^^^^
  File "/home/ubuntu/Festival/venv/lib/python3.12/site-packages/MySQLdb/connections.py", line 195, in __init__
    super().__init__(*args, **kwargs2)
MySQLdb.OperationalError: (1045, "Access denied for user 'root'@'localhost' (using password: YES)")

The above exception was the direct cause of the following exception:

Traceback (most recent call last):
  File "/home/ubuntu/Festival/venv/lib/python3.12/site-packages/django/core/handlers/exception.py", line 55, in inner
    response = get_response(request)
               ^^^^^^^^^^^^^^^^^^^^^
  File "/home/ubuntu/Festival/venv/lib/python3.12/site-packages/django/core/handlers/base.py", line 197, in _get_response
    response = wrapped_callback(request, *callback_args, **callback_kwargs)
               ^^^^^^^^^^^^^^^^^^^^^^^^^^^^^^^^^^^^^^^^^^^^^^^^^^^^^^^^^^^^
  File "/home/ubuntu/Festival/venv/lib/python3.12/site-packages/django/views/decorators/csrf.py", line 65, in _view_wrapper
    return view_func(request, *args, **kwargs)
           ^^^^^^^^^^^^^^^^^^^^^^^^^^^^^^^^^^^
  File "/home/ubuntu/Festival/venv/lib/python3.12/site-packages/django/views/generic/base.py", line 104, in view
    return self.dispatch(request, *args, **kwargs)
           ^^^^^^^^^^^^^^^^^^^^^^^^^^^^^^^^^^^^^^^
  File "/home/ubuntu/Festival/venv/lib/python3.12/site-packages/rest_framework/views.py", line 509, in dispatch
    response = self.handle_exception(exc)
               ^^^^^^^^^^^^^^^^^^^^^^^^^^
  File "/home/ubuntu/Festival/venv/lib/python3.12/site-packages/rest_framework/views.py", line 469, in handle_exception
    self.raise_uncaught_exception(exc)
  File "/home/ubuntu/Festival/venv/lib/python3.12/site-packages/rest_framework/views.py", line 480, in raise_uncaught_exception
    raise exc
  File "/home/ubuntu/Festival/venv/lib/python3.12/site-packages/rest_framework/views.py", line 506, in dispatch
    response = handler(request, *args, **kwargs)
               ^^^^^^^^^^^^^^^^^^^^^^^^^^^^^^^^^
  File "/home/ubuntu/Festival/venv/lib/python3.12/site-packages/rest_framework/generics.py", line 243, in get
    return self.list(request, *args, **kwargs)
           ^^^^^^^^^^^^^^^^^^^^^^^^^^^^^^^^^^^
  File "/home/ubuntu/Festival/venv/lib/python3.12/site-packages/rest_framework/mixins.py", line 46, in list
    return Response(serializer.data)
                    ^^^^^^^^^^^^^^^
  File "/home/ubuntu/Festival/venv/lib/python3.12/site-packages/rest_framework/serializers.py", line 795, in data
    ret = super().data
          ^^^^^^^^^^^^
  File "/home/ubuntu/Festival/venv/lib/python3.12/site-packages/rest_framework/serializers.py", line 249, in data
    self._data = self.to_representation(self.instance)
                 ^^^^^^^^^^^^^^^^^^^^^^^^^^^^^^^^^^^^^
  File "/home/ubuntu/Festival/venv/lib/python3.12/site-packages/rest_framework/serializers.py", line 713, in to_representation
    return [
           ^
  File "/home/ubuntu/Festival/venv/lib/python3.12/site-packages/django/db/models/query.py", line 400, in __iter__
    self._fetch_all()
  File "/home/ubuntu/Festival/venv/lib/python3.12/site-packages/django/db/models/query.py", line 1928, in _fetch_all
    self._result_cache = list(self._iterable_class(self))
                         ^^^^^^^^^^^^^^^^^^^^^^^^^^^^^^^^
  File "/home/ubuntu/Festival/venv/lib/python3.12/site-packages/django/db/models/query.py", line 91, in __iter__
    results = compiler.execute_sql(
              ^^^^^^^^^^^^^^^^^^^^^
  File "/home/ubuntu/Festival/venv/lib/python3.12/site-packages/django/db/models/sql/compiler.py", line 1572, in execute_sql
    cursor = self.connection.cursor()
             ^^^^^^^^^^^^^^^^^^^^^^^^
  File "/home/ubuntu/Festival/venv/lib/python3.12/site-packages/django/utils/asyncio.py", line 26, in inner
    return func(*args, **kwargs)
           ^^^^^^^^^^^^^^^^^^^^^
  File "/home/ubuntu/Festival/venv/lib/python3.12/site-packages/django/db/backends/base/base.py", line 320, in cursor
    return self._cursor()
           ^^^^^^^^^^^^^^
  File "/home/ubuntu/Festival/venv/lib/python3.12/site-packages/django/db/backends/base/base.py", line 296, in _cursor
    self.ensure_connection()
  File "/home/ubuntu/Festival/venv/lib/python3.12/site-packages/django/utils/asyncio.py", line 26, in inner
    return func(*args, **kwargs)
           ^^^^^^^^^^^^^^^^^^^^^
  File "/home/ubuntu/Festival/venv/lib/python3.12/site-packages/django/db/backends/base/base.py", line 278, in ensure_connection
    with self.wrap_database_errors:
  File "/home/ubuntu/Festival/venv/lib/python3.12/site-packages/django/db/utils.py", line 91, in __exit__
    raise dj_exc_value.with_traceback(traceback) from exc_value
  File "/home/ubuntu/Festival/venv/lib/python3.12/site-packages/django/db/backends/base/base.py", line 279, in ensure_connection
    self.connect()
  File "/home/ubuntu/Festival/venv/lib/python3.12/site-packages/django/utils/asyncio.py", line 26, in inner
    return func(*args, **kwargs)
           ^^^^^^^^^^^^^^^^^^^^^
  File "/home/ubuntu/Festival/venv/lib/python3.12/site-packages/django/db/backends/base/base.py", line 256, in connect
    self.connection = self.get_new_connection(conn_params)
                      ^^^^^^^^^^^^^^^^^^^^^^^^^^^^^^^^^^^^
  File "/home/ubuntu/Festival/venv/lib/python3.12/site-packages/django/utils/asyncio.py", line 26, in inner
    return func(*args, **kwargs)
           ^^^^^^^^^^^^^^^^^^^^^
  File "/home/ubuntu/Festival/venv/lib/python3.12/site-packages/django/db/backends/mysql/base.py", line 256, in get_new_connection
    connection = Database.connect(**conn_params)
                 ^^^^^^^^^^^^^^^^^^^^^^^^^^^^^^^
  File "/home/ubuntu/Festival/venv/lib/python3.12/site-packages/MySQLdb/__init__.py", line 121, in Connect
    return Connection(*args, **kwargs)
           ^^^^^^^^^^^^^^^^^^^^^^^^^^^
  File "/home/ubuntu/Festival/venv/lib/python3.12/site-packages/MySQLdb/connections.py", line 195, in __init__
    super().__init__(*args, **kwargs2)
django.db.utils.OperationalError: (1045, "Access denied for user 'root'@'localhost' (using password: YES)")
2024-11-19 03:41:40 [WARNING] django.request (log): Not Found: /api/
2024-11-19 03:41:45 [INFO] api.views (views): Fetching all festivals.
2024-11-19 03:41:45 [ERROR] django.request (log): Internal Server Error: /api/festivals/
Traceback (most recent call last):
  File "/home/ubuntu/Festival/venv/lib/python3.12/site-packages/django/db/backends/base/base.py", line 279, in ensure_connection
    self.connect()
  File "/home/ubuntu/Festival/venv/lib/python3.12/site-packages/django/utils/asyncio.py", line 26, in inner
    return func(*args, **kwargs)
           ^^^^^^^^^^^^^^^^^^^^^
  File "/home/ubuntu/Festival/venv/lib/python3.12/site-packages/django/db/backends/base/base.py", line 256, in connect
    self.connection = self.get_new_connection(conn_params)
                      ^^^^^^^^^^^^^^^^^^^^^^^^^^^^^^^^^^^^
  File "/home/ubuntu/Festival/venv/lib/python3.12/site-packages/django/utils/asyncio.py", line 26, in inner
    return func(*args, **kwargs)
           ^^^^^^^^^^^^^^^^^^^^^
  File "/home/ubuntu/Festival/venv/lib/python3.12/site-packages/django/db/backends/mysql/base.py", line 256, in get_new_connection
    connection = Database.connect(**conn_params)
                 ^^^^^^^^^^^^^^^^^^^^^^^^^^^^^^^
  File "/home/ubuntu/Festival/venv/lib/python3.12/site-packages/MySQLdb/__init__.py", line 121, in Connect
    return Connection(*args, **kwargs)
           ^^^^^^^^^^^^^^^^^^^^^^^^^^^
  File "/home/ubuntu/Festival/venv/lib/python3.12/site-packages/MySQLdb/connections.py", line 195, in __init__
    super().__init__(*args, **kwargs2)
MySQLdb.OperationalError: (1045, "Access denied for user 'root'@'localhost' (using password: YES)")

The above exception was the direct cause of the following exception:

Traceback (most recent call last):
  File "/home/ubuntu/Festival/venv/lib/python3.12/site-packages/django/core/handlers/exception.py", line 55, in inner
    response = get_response(request)
               ^^^^^^^^^^^^^^^^^^^^^
  File "/home/ubuntu/Festival/venv/lib/python3.12/site-packages/django/core/handlers/base.py", line 197, in _get_response
    response = wrapped_callback(request, *callback_args, **callback_kwargs)
               ^^^^^^^^^^^^^^^^^^^^^^^^^^^^^^^^^^^^^^^^^^^^^^^^^^^^^^^^^^^^
  File "/home/ubuntu/Festival/venv/lib/python3.12/site-packages/django/views/decorators/csrf.py", line 65, in _view_wrapper
    return view_func(request, *args, **kwargs)
           ^^^^^^^^^^^^^^^^^^^^^^^^^^^^^^^^^^^
  File "/home/ubuntu/Festival/venv/lib/python3.12/site-packages/django/views/generic/base.py", line 104, in view
    return self.dispatch(request, *args, **kwargs)
           ^^^^^^^^^^^^^^^^^^^^^^^^^^^^^^^^^^^^^^^
  File "/home/ubuntu/Festival/venv/lib/python3.12/site-packages/rest_framework/views.py", line 509, in dispatch
    response = self.handle_exception(exc)
               ^^^^^^^^^^^^^^^^^^^^^^^^^^
  File "/home/ubuntu/Festival/venv/lib/python3.12/site-packages/rest_framework/views.py", line 469, in handle_exception
    self.raise_uncaught_exception(exc)
  File "/home/ubuntu/Festival/venv/lib/python3.12/site-packages/rest_framework/views.py", line 480, in raise_uncaught_exception
    raise exc
  File "/home/ubuntu/Festival/venv/lib/python3.12/site-packages/rest_framework/views.py", line 506, in dispatch
    response = handler(request, *args, **kwargs)
               ^^^^^^^^^^^^^^^^^^^^^^^^^^^^^^^^^
  File "/home/ubuntu/Festival/venv/lib/python3.12/site-packages/rest_framework/generics.py", line 243, in get
    return self.list(request, *args, **kwargs)
           ^^^^^^^^^^^^^^^^^^^^^^^^^^^^^^^^^^^
  File "/home/ubuntu/Festival/venv/lib/python3.12/site-packages/rest_framework/mixins.py", line 46, in list
    return Response(serializer.data)
                    ^^^^^^^^^^^^^^^
  File "/home/ubuntu/Festival/venv/lib/python3.12/site-packages/rest_framework/serializers.py", line 795, in data
    ret = super().data
          ^^^^^^^^^^^^
  File "/home/ubuntu/Festival/venv/lib/python3.12/site-packages/rest_framework/serializers.py", line 249, in data
    self._data = self.to_representation(self.instance)
                 ^^^^^^^^^^^^^^^^^^^^^^^^^^^^^^^^^^^^^
  File "/home/ubuntu/Festival/venv/lib/python3.12/site-packages/rest_framework/serializers.py", line 713, in to_representation
    return [
           ^
  File "/home/ubuntu/Festival/venv/lib/python3.12/site-packages/django/db/models/query.py", line 400, in __iter__
    self._fetch_all()
  File "/home/ubuntu/Festival/venv/lib/python3.12/site-packages/django/db/models/query.py", line 1928, in _fetch_all
    self._result_cache = list(self._iterable_class(self))
                         ^^^^^^^^^^^^^^^^^^^^^^^^^^^^^^^^
  File "/home/ubuntu/Festival/venv/lib/python3.12/site-packages/django/db/models/query.py", line 91, in __iter__
    results = compiler.execute_sql(
              ^^^^^^^^^^^^^^^^^^^^^
  File "/home/ubuntu/Festival/venv/lib/python3.12/site-packages/django/db/models/sql/compiler.py", line 1572, in execute_sql
    cursor = self.connection.cursor()
             ^^^^^^^^^^^^^^^^^^^^^^^^
  File "/home/ubuntu/Festival/venv/lib/python3.12/site-packages/django/utils/asyncio.py", line 26, in inner
    return func(*args, **kwargs)
           ^^^^^^^^^^^^^^^^^^^^^
  File "/home/ubuntu/Festival/venv/lib/python3.12/site-packages/django/db/backends/base/base.py", line 320, in cursor
    return self._cursor()
           ^^^^^^^^^^^^^^
  File "/home/ubuntu/Festival/venv/lib/python3.12/site-packages/django/db/backends/base/base.py", line 296, in _cursor
    self.ensure_connection()
  File "/home/ubuntu/Festival/venv/lib/python3.12/site-packages/django/utils/asyncio.py", line 26, in inner
    return func(*args, **kwargs)
           ^^^^^^^^^^^^^^^^^^^^^
  File "/home/ubuntu/Festival/venv/lib/python3.12/site-packages/django/db/backends/base/base.py", line 278, in ensure_connection
    with self.wrap_database_errors:
  File "/home/ubuntu/Festival/venv/lib/python3.12/site-packages/django/db/utils.py", line 91, in __exit__
    raise dj_exc_value.with_traceback(traceback) from exc_value
  File "/home/ubuntu/Festival/venv/lib/python3.12/site-packages/django/db/backends/base/base.py", line 279, in ensure_connection
    self.connect()
  File "/home/ubuntu/Festival/venv/lib/python3.12/site-packages/django/utils/asyncio.py", line 26, in inner
    return func(*args, **kwargs)
           ^^^^^^^^^^^^^^^^^^^^^
  File "/home/ubuntu/Festival/venv/lib/python3.12/site-packages/django/db/backends/base/base.py", line 256, in connect
    self.connection = self.get_new_connection(conn_params)
                      ^^^^^^^^^^^^^^^^^^^^^^^^^^^^^^^^^^^^
  File "/home/ubuntu/Festival/venv/lib/python3.12/site-packages/django/utils/asyncio.py", line 26, in inner
    return func(*args, **kwargs)
           ^^^^^^^^^^^^^^^^^^^^^
  File "/home/ubuntu/Festival/venv/lib/python3.12/site-packages/django/db/backends/mysql/base.py", line 256, in get_new_connection
    connection = Database.connect(**conn_params)
                 ^^^^^^^^^^^^^^^^^^^^^^^^^^^^^^^
  File "/home/ubuntu/Festival/venv/lib/python3.12/site-packages/MySQLdb/__init__.py", line 121, in Connect
    return Connection(*args, **kwargs)
           ^^^^^^^^^^^^^^^^^^^^^^^^^^^
  File "/home/ubuntu/Festival/venv/lib/python3.12/site-packages/MySQLdb/connections.py", line 195, in __init__
    super().__init__(*args, **kwargs2)
django.db.utils.OperationalError: (1045, "Access denied for user 'root'@'localhost' (using password: YES)")
2024-11-19 03:42:44 [INFO] api.views (views): Fetching all festivals.
2024-11-19 03:42:44 [ERROR] django.request (log): Internal Server Error: /api/festivals/
Traceback (most recent call last):
  File "/home/ubuntu/Festival/venv/lib/python3.12/site-packages/django/db/backends/base/base.py", line 279, in ensure_connection
    self.connect()
  File "/home/ubuntu/Festival/venv/lib/python3.12/site-packages/django/utils/asyncio.py", line 26, in inner
    return func(*args, **kwargs)
           ^^^^^^^^^^^^^^^^^^^^^
  File "/home/ubuntu/Festival/venv/lib/python3.12/site-packages/django/db/backends/base/base.py", line 256, in connect
    self.connection = self.get_new_connection(conn_params)
                      ^^^^^^^^^^^^^^^^^^^^^^^^^^^^^^^^^^^^
  File "/home/ubuntu/Festival/venv/lib/python3.12/site-packages/django/utils/asyncio.py", line 26, in inner
    return func(*args, **kwargs)
           ^^^^^^^^^^^^^^^^^^^^^
  File "/home/ubuntu/Festival/venv/lib/python3.12/site-packages/django/db/backends/mysql/base.py", line 256, in get_new_connection
    connection = Database.connect(**conn_params)
                 ^^^^^^^^^^^^^^^^^^^^^^^^^^^^^^^
  File "/home/ubuntu/Festival/venv/lib/python3.12/site-packages/MySQLdb/__init__.py", line 121, in Connect
    return Connection(*args, **kwargs)
           ^^^^^^^^^^^^^^^^^^^^^^^^^^^
  File "/home/ubuntu/Festival/venv/lib/python3.12/site-packages/MySQLdb/connections.py", line 195, in __init__
    super().__init__(*args, **kwargs2)
MySQLdb.OperationalError: (1045, "Access denied for user 'root'@'localhost' (using password: YES)")

The above exception was the direct cause of the following exception:

Traceback (most recent call last):
  File "/home/ubuntu/Festival/venv/lib/python3.12/site-packages/django/core/handlers/exception.py", line 55, in inner
    response = get_response(request)
               ^^^^^^^^^^^^^^^^^^^^^
  File "/home/ubuntu/Festival/venv/lib/python3.12/site-packages/django/core/handlers/base.py", line 197, in _get_response
    response = wrapped_callback(request, *callback_args, **callback_kwargs)
               ^^^^^^^^^^^^^^^^^^^^^^^^^^^^^^^^^^^^^^^^^^^^^^^^^^^^^^^^^^^^
  File "/home/ubuntu/Festival/venv/lib/python3.12/site-packages/django/views/decorators/csrf.py", line 65, in _view_wrapper
    return view_func(request, *args, **kwargs)
           ^^^^^^^^^^^^^^^^^^^^^^^^^^^^^^^^^^^
  File "/home/ubuntu/Festival/venv/lib/python3.12/site-packages/django/views/generic/base.py", line 104, in view
    return self.dispatch(request, *args, **kwargs)
           ^^^^^^^^^^^^^^^^^^^^^^^^^^^^^^^^^^^^^^^
  File "/home/ubuntu/Festival/venv/lib/python3.12/site-packages/rest_framework/views.py", line 509, in dispatch
    response = self.handle_exception(exc)
               ^^^^^^^^^^^^^^^^^^^^^^^^^^
  File "/home/ubuntu/Festival/venv/lib/python3.12/site-packages/rest_framework/views.py", line 469, in handle_exception
    self.raise_uncaught_exception(exc)
  File "/home/ubuntu/Festival/venv/lib/python3.12/site-packages/rest_framework/views.py", line 480, in raise_uncaught_exception
    raise exc
  File "/home/ubuntu/Festival/venv/lib/python3.12/site-packages/rest_framework/views.py", line 506, in dispatch
    response = handler(request, *args, **kwargs)
               ^^^^^^^^^^^^^^^^^^^^^^^^^^^^^^^^^
  File "/home/ubuntu/Festival/venv/lib/python3.12/site-packages/rest_framework/generics.py", line 243, in get
    return self.list(request, *args, **kwargs)
           ^^^^^^^^^^^^^^^^^^^^^^^^^^^^^^^^^^^
  File "/home/ubuntu/Festival/venv/lib/python3.12/site-packages/rest_framework/mixins.py", line 46, in list
    return Response(serializer.data)
                    ^^^^^^^^^^^^^^^
  File "/home/ubuntu/Festival/venv/lib/python3.12/site-packages/rest_framework/serializers.py", line 795, in data
    ret = super().data
          ^^^^^^^^^^^^
  File "/home/ubuntu/Festival/venv/lib/python3.12/site-packages/rest_framework/serializers.py", line 249, in data
    self._data = self.to_representation(self.instance)
                 ^^^^^^^^^^^^^^^^^^^^^^^^^^^^^^^^^^^^^
  File "/home/ubuntu/Festival/venv/lib/python3.12/site-packages/rest_framework/serializers.py", line 713, in to_representation
    return [
           ^
  File "/home/ubuntu/Festival/venv/lib/python3.12/site-packages/django/db/models/query.py", line 400, in __iter__
    self._fetch_all()
  File "/home/ubuntu/Festival/venv/lib/python3.12/site-packages/django/db/models/query.py", line 1928, in _fetch_all
    self._result_cache = list(self._iterable_class(self))
                         ^^^^^^^^^^^^^^^^^^^^^^^^^^^^^^^^
  File "/home/ubuntu/Festival/venv/lib/python3.12/site-packages/django/db/models/query.py", line 91, in __iter__
    results = compiler.execute_sql(
              ^^^^^^^^^^^^^^^^^^^^^
  File "/home/ubuntu/Festival/venv/lib/python3.12/site-packages/django/db/models/sql/compiler.py", line 1572, in execute_sql
    cursor = self.connection.cursor()
             ^^^^^^^^^^^^^^^^^^^^^^^^
  File "/home/ubuntu/Festival/venv/lib/python3.12/site-packages/django/utils/asyncio.py", line 26, in inner
    return func(*args, **kwargs)
           ^^^^^^^^^^^^^^^^^^^^^
  File "/home/ubuntu/Festival/venv/lib/python3.12/site-packages/django/db/backends/base/base.py", line 320, in cursor
    return self._cursor()
           ^^^^^^^^^^^^^^
  File "/home/ubuntu/Festival/venv/lib/python3.12/site-packages/django/db/backends/base/base.py", line 296, in _cursor
    self.ensure_connection()
  File "/home/ubuntu/Festival/venv/lib/python3.12/site-packages/django/utils/asyncio.py", line 26, in inner
    return func(*args, **kwargs)
           ^^^^^^^^^^^^^^^^^^^^^
  File "/home/ubuntu/Festival/venv/lib/python3.12/site-packages/django/db/backends/base/base.py", line 278, in ensure_connection
    with self.wrap_database_errors:
  File "/home/ubuntu/Festival/venv/lib/python3.12/site-packages/django/db/utils.py", line 91, in __exit__
    raise dj_exc_value.with_traceback(traceback) from exc_value
  File "/home/ubuntu/Festival/venv/lib/python3.12/site-packages/django/db/backends/base/base.py", line 279, in ensure_connection
    self.connect()
  File "/home/ubuntu/Festival/venv/lib/python3.12/site-packages/django/utils/asyncio.py", line 26, in inner
    return func(*args, **kwargs)
           ^^^^^^^^^^^^^^^^^^^^^
  File "/home/ubuntu/Festival/venv/lib/python3.12/site-packages/django/db/backends/base/base.py", line 256, in connect
    self.connection = self.get_new_connection(conn_params)
                      ^^^^^^^^^^^^^^^^^^^^^^^^^^^^^^^^^^^^
  File "/home/ubuntu/Festival/venv/lib/python3.12/site-packages/django/utils/asyncio.py", line 26, in inner
    return func(*args, **kwargs)
           ^^^^^^^^^^^^^^^^^^^^^
  File "/home/ubuntu/Festival/venv/lib/python3.12/site-packages/django/db/backends/mysql/base.py", line 256, in get_new_connection
    connection = Database.connect(**conn_params)
                 ^^^^^^^^^^^^^^^^^^^^^^^^^^^^^^^
  File "/home/ubuntu/Festival/venv/lib/python3.12/site-packages/MySQLdb/__init__.py", line 121, in Connect
    return Connection(*args, **kwargs)
           ^^^^^^^^^^^^^^^^^^^^^^^^^^^
  File "/home/ubuntu/Festival/venv/lib/python3.12/site-packages/MySQLdb/connections.py", line 195, in __init__
    super().__init__(*args, **kwargs2)
django.db.utils.OperationalError: (1045, "Access denied for user 'root'@'localhost' (using password: YES)")
2024-11-19 03:42:47 [INFO] api.views (views): Fetching all festivals.
2024-11-19 03:42:47 [ERROR] django.request (log): Internal Server Error: /api/festivals/
Traceback (most recent call last):
  File "/home/ubuntu/Festival/venv/lib/python3.12/site-packages/django/db/backends/base/base.py", line 279, in ensure_connection
    self.connect()
  File "/home/ubuntu/Festival/venv/lib/python3.12/site-packages/django/utils/asyncio.py", line 26, in inner
    return func(*args, **kwargs)
           ^^^^^^^^^^^^^^^^^^^^^
  File "/home/ubuntu/Festival/venv/lib/python3.12/site-packages/django/db/backends/base/base.py", line 256, in connect
    self.connection = self.get_new_connection(conn_params)
                      ^^^^^^^^^^^^^^^^^^^^^^^^^^^^^^^^^^^^
  File "/home/ubuntu/Festival/venv/lib/python3.12/site-packages/django/utils/asyncio.py", line 26, in inner
    return func(*args, **kwargs)
           ^^^^^^^^^^^^^^^^^^^^^
  File "/home/ubuntu/Festival/venv/lib/python3.12/site-packages/django/db/backends/mysql/base.py", line 256, in get_new_connection
    connection = Database.connect(**conn_params)
                 ^^^^^^^^^^^^^^^^^^^^^^^^^^^^^^^
  File "/home/ubuntu/Festival/venv/lib/python3.12/site-packages/MySQLdb/__init__.py", line 121, in Connect
    return Connection(*args, **kwargs)
           ^^^^^^^^^^^^^^^^^^^^^^^^^^^
  File "/home/ubuntu/Festival/venv/lib/python3.12/site-packages/MySQLdb/connections.py", line 195, in __init__
    super().__init__(*args, **kwargs2)
MySQLdb.OperationalError: (1045, "Access denied for user 'root'@'localhost' (using password: YES)")

The above exception was the direct cause of the following exception:

Traceback (most recent call last):
  File "/home/ubuntu/Festival/venv/lib/python3.12/site-packages/django/core/handlers/exception.py", line 55, in inner
    response = get_response(request)
               ^^^^^^^^^^^^^^^^^^^^^
  File "/home/ubuntu/Festival/venv/lib/python3.12/site-packages/django/core/handlers/base.py", line 197, in _get_response
    response = wrapped_callback(request, *callback_args, **callback_kwargs)
               ^^^^^^^^^^^^^^^^^^^^^^^^^^^^^^^^^^^^^^^^^^^^^^^^^^^^^^^^^^^^
  File "/home/ubuntu/Festival/venv/lib/python3.12/site-packages/django/views/decorators/csrf.py", line 65, in _view_wrapper
    return view_func(request, *args, **kwargs)
           ^^^^^^^^^^^^^^^^^^^^^^^^^^^^^^^^^^^
  File "/home/ubuntu/Festival/venv/lib/python3.12/site-packages/django/views/generic/base.py", line 104, in view
    return self.dispatch(request, *args, **kwargs)
           ^^^^^^^^^^^^^^^^^^^^^^^^^^^^^^^^^^^^^^^
  File "/home/ubuntu/Festival/venv/lib/python3.12/site-packages/rest_framework/views.py", line 509, in dispatch
    response = self.handle_exception(exc)
               ^^^^^^^^^^^^^^^^^^^^^^^^^^
  File "/home/ubuntu/Festival/venv/lib/python3.12/site-packages/rest_framework/views.py", line 469, in handle_exception
    self.raise_uncaught_exception(exc)
  File "/home/ubuntu/Festival/venv/lib/python3.12/site-packages/rest_framework/views.py", line 480, in raise_uncaught_exception
    raise exc
  File "/home/ubuntu/Festival/venv/lib/python3.12/site-packages/rest_framework/views.py", line 506, in dispatch
    response = handler(request, *args, **kwargs)
               ^^^^^^^^^^^^^^^^^^^^^^^^^^^^^^^^^
  File "/home/ubuntu/Festival/venv/lib/python3.12/site-packages/rest_framework/generics.py", line 243, in get
    return self.list(request, *args, **kwargs)
           ^^^^^^^^^^^^^^^^^^^^^^^^^^^^^^^^^^^
  File "/home/ubuntu/Festival/venv/lib/python3.12/site-packages/rest_framework/mixins.py", line 46, in list
    return Response(serializer.data)
                    ^^^^^^^^^^^^^^^
  File "/home/ubuntu/Festival/venv/lib/python3.12/site-packages/rest_framework/serializers.py", line 795, in data
    ret = super().data
          ^^^^^^^^^^^^
  File "/home/ubuntu/Festival/venv/lib/python3.12/site-packages/rest_framework/serializers.py", line 249, in data
    self._data = self.to_representation(self.instance)
                 ^^^^^^^^^^^^^^^^^^^^^^^^^^^^^^^^^^^^^
  File "/home/ubuntu/Festival/venv/lib/python3.12/site-packages/rest_framework/serializers.py", line 713, in to_representation
    return [
           ^
  File "/home/ubuntu/Festival/venv/lib/python3.12/site-packages/django/db/models/query.py", line 400, in __iter__
    self._fetch_all()
  File "/home/ubuntu/Festival/venv/lib/python3.12/site-packages/django/db/models/query.py", line 1928, in _fetch_all
    self._result_cache = list(self._iterable_class(self))
                         ^^^^^^^^^^^^^^^^^^^^^^^^^^^^^^^^
  File "/home/ubuntu/Festival/venv/lib/python3.12/site-packages/django/db/models/query.py", line 91, in __iter__
    results = compiler.execute_sql(
              ^^^^^^^^^^^^^^^^^^^^^
  File "/home/ubuntu/Festival/venv/lib/python3.12/site-packages/django/db/models/sql/compiler.py", line 1572, in execute_sql
    cursor = self.connection.cursor()
             ^^^^^^^^^^^^^^^^^^^^^^^^
  File "/home/ubuntu/Festival/venv/lib/python3.12/site-packages/django/utils/asyncio.py", line 26, in inner
    return func(*args, **kwargs)
           ^^^^^^^^^^^^^^^^^^^^^
  File "/home/ubuntu/Festival/venv/lib/python3.12/site-packages/django/db/backends/base/base.py", line 320, in cursor
    return self._cursor()
           ^^^^^^^^^^^^^^
  File "/home/ubuntu/Festival/venv/lib/python3.12/site-packages/django/db/backends/base/base.py", line 296, in _cursor
    self.ensure_connection()
  File "/home/ubuntu/Festival/venv/lib/python3.12/site-packages/django/utils/asyncio.py", line 26, in inner
    return func(*args, **kwargs)
           ^^^^^^^^^^^^^^^^^^^^^
  File "/home/ubuntu/Festival/venv/lib/python3.12/site-packages/django/db/backends/base/base.py", line 278, in ensure_connection
    with self.wrap_database_errors:
  File "/home/ubuntu/Festival/venv/lib/python3.12/site-packages/django/db/utils.py", line 91, in __exit__
    raise dj_exc_value.with_traceback(traceback) from exc_value
  File "/home/ubuntu/Festival/venv/lib/python3.12/site-packages/django/db/backends/base/base.py", line 279, in ensure_connection
    self.connect()
  File "/home/ubuntu/Festival/venv/lib/python3.12/site-packages/django/utils/asyncio.py", line 26, in inner
    return func(*args, **kwargs)
           ^^^^^^^^^^^^^^^^^^^^^
  File "/home/ubuntu/Festival/venv/lib/python3.12/site-packages/django/db/backends/base/base.py", line 256, in connect
    self.connection = self.get_new_connection(conn_params)
                      ^^^^^^^^^^^^^^^^^^^^^^^^^^^^^^^^^^^^
  File "/home/ubuntu/Festival/venv/lib/python3.12/site-packages/django/utils/asyncio.py", line 26, in inner
    return func(*args, **kwargs)
           ^^^^^^^^^^^^^^^^^^^^^
  File "/home/ubuntu/Festival/venv/lib/python3.12/site-packages/django/db/backends/mysql/base.py", line 256, in get_new_connection
    connection = Database.connect(**conn_params)
                 ^^^^^^^^^^^^^^^^^^^^^^^^^^^^^^^
  File "/home/ubuntu/Festival/venv/lib/python3.12/site-packages/MySQLdb/__init__.py", line 121, in Connect
    return Connection(*args, **kwargs)
           ^^^^^^^^^^^^^^^^^^^^^^^^^^^
  File "/home/ubuntu/Festival/venv/lib/python3.12/site-packages/MySQLdb/connections.py", line 195, in __init__
    super().__init__(*args, **kwargs2)
django.db.utils.OperationalError: (1045, "Access denied for user 'root'@'localhost' (using password: YES)")
2024-11-19 03:44:44 [DEBUG] faiss.loader (loader): Environment variable FAISS_OPT_LEVEL is not set, so let's pick the instruction set according to the current CPU
2024-11-19 03:44:44 [INFO] faiss.loader (loader): Loading faiss with AVX2 support.
2024-11-19 03:44:44 [INFO] faiss.loader (loader): Successfully loaded faiss with AVX2 support.
2024-11-19 03:44:45 [DEBUG] pydot (__init__): pydot initializing
2024-11-19 03:44:45 [DEBUG] pydot (__init__): pydot 3.0.2
2024-11-19 03:44:45 [DEBUG] pydot.dot_parser (dot_parser): pydot dot_parser module initializing
2024-11-19 03:44:45 [DEBUG] pydot.core (core): pydot core module initializing
2024-11-19 03:45:34 [DEBUG] faiss.loader (loader): Environment variable FAISS_OPT_LEVEL is not set, so let's pick the instruction set according to the current CPU
2024-11-19 03:45:34 [INFO] faiss.loader (loader): Loading faiss with AVX2 support.
2024-11-19 03:45:34 [INFO] faiss.loader (loader): Successfully loaded faiss with AVX2 support.
2024-11-19 03:45:35 [DEBUG] pydot (__init__): pydot initializing
2024-11-19 03:45:35 [DEBUG] pydot (__init__): pydot 3.0.2
2024-11-19 03:45:35 [DEBUG] pydot.dot_parser (dot_parser): pydot dot_parser module initializing
2024-11-19 03:45:35 [DEBUG] pydot.core (core): pydot core module initializing
2024-11-19 03:45:48 [DEBUG] faiss.loader (loader): Environment variable FAISS_OPT_LEVEL is not set, so let's pick the instruction set according to the current CPU
2024-11-19 03:45:48 [INFO] faiss.loader (loader): Loading faiss with AVX2 support.
2024-11-19 03:45:48 [INFO] faiss.loader (loader): Successfully loaded faiss with AVX2 support.
2024-11-19 03:45:49 [DEBUG] pydot (__init__): pydot initializing
2024-11-19 03:45:49 [DEBUG] pydot (__init__): pydot 3.0.2
2024-11-19 03:45:49 [DEBUG] pydot.dot_parser (dot_parser): pydot dot_parser module initializing
2024-11-19 03:45:49 [DEBUG] pydot.core (core): pydot core module initializing
2024-11-19 03:46:31 [DEBUG] faiss.loader (loader): Environment variable FAISS_OPT_LEVEL is not set, so let's pick the instruction set according to the current CPU
2024-11-19 03:46:31 [INFO] faiss.loader (loader): Loading faiss with AVX2 support.
2024-11-19 03:46:31 [INFO] faiss.loader (loader): Successfully loaded faiss with AVX2 support.
2024-11-19 03:46:32 [DEBUG] pydot (__init__): pydot initializing
2024-11-19 03:46:32 [DEBUG] pydot (__init__): pydot 3.0.2
2024-11-19 03:46:32 [DEBUG] pydot.dot_parser (dot_parser): pydot dot_parser module initializing
2024-11-19 03:46:32 [DEBUG] pydot.core (core): pydot core module initializing
2024-11-19 03:46:34 [INFO] api.views (views): Fetching all festivals.
2024-11-19 03:46:34 [INFO] api.views (views): Fetching all festivals.
2024-11-19 03:47:12 [INFO] api.views (views): Fetching all festivals.
2024-11-19 03:47:12 [INFO] api.views (views): Fetching all festivals.
2024-11-19 03:55:45 [DEBUG] faiss.loader (loader): Environment variable FAISS_OPT_LEVEL is not set, so let's pick the instruction set according to the current CPU
2024-11-19 03:55:45 [INFO] faiss.loader (loader): Loading faiss with AVX2 support.
2024-11-19 03:55:45 [INFO] faiss.loader (loader): Successfully loaded faiss with AVX2 support.
2024-11-19 03:55:45 [DEBUG] pydot (__init__): pydot initializing
2024-11-19 03:55:45 [DEBUG] pydot (__init__): pydot 3.0.2
2024-11-19 03:55:45 [DEBUG] pydot.dot_parser (dot_parser): pydot dot_parser module initializing
2024-11-19 03:55:45 [DEBUG] pydot.core (core): pydot core module initializing
2024-11-19 03:55:47 [WARNING] django.request (log): Not Found: /api/api/festivals/
2024-11-19 03:55:47 [WARNING] django.request (log): Not Found: /api/api/festivals/
2024-11-19 03:55:48 [DEBUG] faiss.loader (loader): Environment variable FAISS_OPT_LEVEL is not set, so let's pick the instruction set according to the current CPU
2024-11-19 03:55:48 [INFO] faiss.loader (loader): Loading faiss with AVX2 support.
2024-11-19 03:55:48 [INFO] faiss.loader (loader): Successfully loaded faiss with AVX2 support.
2024-11-19 03:55:49 [DEBUG] pydot (__init__): pydot initializing
2024-11-19 03:55:49 [DEBUG] pydot (__init__): pydot 3.0.2
2024-11-19 03:55:49 [DEBUG] pydot.dot_parser (dot_parser): pydot dot_parser module initializing
2024-11-19 03:55:49 [DEBUG] pydot.core (core): pydot core module initializing
2024-11-19 03:55:51 [INFO] api.views (views): Fetching all festivals.
2024-11-19 03:55:51 [INFO] api.views (views): Fetching all festivals.
2024-11-19 04:00:53 [WARNING] django.request (log): Not Found: /api/api/festivals/
2024-11-19 04:00:53 [WARNING] django.request (log): Not Found: /api/api/festivals/
2024-11-19 04:48:35 [WARNING] django.request (log): Not Found: /api/api/festivals/
2024-11-19 04:48:35 [WARNING] django.request (log): Not Found: /api/api/festivals/
