2024-11-15 09:45:03 [INFO] django.utils.autoreload (autoreload): Watching for file changes with StatReloader
2024-11-15 09:45:17 [INFO] api.views (views): Fetching all festivals.
2024-11-15 09:45:20 [INFO] api.views (views): Fetched festival with ID 19. View count incremented.
2024-11-15 09:45:20 [INFO] api.views (views): Fetching all comments.
2024-11-15 09:45:20 [INFO] api.views (views): Fetching all hashtags.
2024-11-15 09:45:27 [DEBUG] urllib3.connectionpool (connectionpool): Starting new HTTP connection (1): 10.1.1.4:5000
2024-11-15 09:47:42 [ERROR] api.views (views): ChatWithBotView: Error communicating with chatbot API.
URL: http://10.1.1.4:5000/chat
User Input: 입장료 알려줘
Exception: HTTPConnectionPool(host='10.1.1.4', port=5000): Max retries exceeded with url: /chat (Caused by ConnectTimeoutError(<urllib3.connection.HTTPConnection object at 0x71c9617d1a30>, 'Connection to 10.1.1.4 timed out. (connect timeout=None)'))
Traceback: Traceback (most recent call last):
  File "/home/skdudgns/Festival/venv/lib/python3.12/site-packages/urllib3/connection.py", line 199, in _new_conn
    sock = connection.create_connection(
           ^^^^^^^^^^^^^^^^^^^^^^^^^^^^^
  File "/home/skdudgns/Festival/venv/lib/python3.12/site-packages/urllib3/util/connection.py", line 85, in create_connection
    raise err
  File "/home/skdudgns/Festival/venv/lib/python3.12/site-packages/urllib3/util/connection.py", line 73, in create_connection
    sock.connect(sa)
TimeoutError: [Errno 110] Connection timed out

The above exception was the direct cause of the following exception:

Traceback (most recent call last):
  File "/home/skdudgns/Festival/venv/lib/python3.12/site-packages/urllib3/connectionpool.py", line 789, in urlopen
    response = self._make_request(
               ^^^^^^^^^^^^^^^^^^^
  File "/home/skdudgns/Festival/venv/lib/python3.12/site-packages/urllib3/connectionpool.py", line 495, in _make_request
    conn.request(
  File "/home/skdudgns/Festival/venv/lib/python3.12/site-packages/urllib3/connection.py", line 441, in request
    self.endheaders()
  File "/usr/lib/python3.12/http/client.py", line 1331, in endheaders
    self._send_output(message_body, encode_chunked=encode_chunked)
  File "/usr/lib/python3.12/http/client.py", line 1091, in _send_output
    self.send(msg)
  File "/usr/lib/python3.12/http/client.py", line 1035, in send
    self.connect()
  File "/home/skdudgns/Festival/venv/lib/python3.12/site-packages/urllib3/connection.py", line 279, in connect
    self.sock = self._new_conn()
                ^^^^^^^^^^^^^^^^
  File "/home/skdudgns/Festival/venv/lib/python3.12/site-packages/urllib3/connection.py", line 208, in _new_conn
    raise ConnectTimeoutError(
urllib3.exceptions.ConnectTimeoutError: (<urllib3.connection.HTTPConnection object at 0x71c9617d1a30>, 'Connection to 10.1.1.4 timed out. (connect timeout=None)')

The above exception was the direct cause of the following exception:

Traceback (most recent call last):
  File "/home/skdudgns/Festival/venv/lib/python3.12/site-packages/requests/adapters.py", line 667, in send
    resp = conn.urlopen(
           ^^^^^^^^^^^^^
  File "/home/skdudgns/Festival/venv/lib/python3.12/site-packages/urllib3/connectionpool.py", line 843, in urlopen
    retries = retries.increment(
              ^^^^^^^^^^^^^^^^^^
  File "/home/skdudgns/Festival/venv/lib/python3.12/site-packages/urllib3/util/retry.py", line 519, in increment
    raise MaxRetryError(_pool, url, reason) from reason  # type: ignore[arg-type]
    ^^^^^^^^^^^^^^^^^^^^^^^^^^^^^^^^^^^^^^^^^^^^^^^^^^^
urllib3.exceptions.MaxRetryError: HTTPConnectionPool(host='10.1.1.4', port=5000): Max retries exceeded with url: /chat (Caused by ConnectTimeoutError(<urllib3.connection.HTTPConnection object at 0x71c9617d1a30>, 'Connection to 10.1.1.4 timed out. (connect timeout=None)'))

During handling of the above exception, another exception occurred:

Traceback (most recent call last):
  File "/home/skdudgns/Festival/backend/api/views.py", line 249, in post
    response = requests.post(url, json={"input_user": user_input})
               ^^^^^^^^^^^^^^^^^^^^^^^^^^^^^^^^^^^^^^^^^^^^^^^^^^^
  File "/home/skdudgns/Festival/venv/lib/python3.12/site-packages/requests/api.py", line 115, in post
    return request("post", url, data=data, json=json, **kwargs)
           ^^^^^^^^^^^^^^^^^^^^^^^^^^^^^^^^^^^^^^^^^^^^^^^^^^^^
  File "/home/skdudgns/Festival/venv/lib/python3.12/site-packages/requests/api.py", line 59, in request
    return session.request(method=method, url=url, **kwargs)
           ^^^^^^^^^^^^^^^^^^^^^^^^^^^^^^^^^^^^^^^^^^^^^^^^^
  File "/home/skdudgns/Festival/venv/lib/python3.12/site-packages/requests/sessions.py", line 589, in request
    resp = self.send(prep, **send_kwargs)
           ^^^^^^^^^^^^^^^^^^^^^^^^^^^^^^
  File "/home/skdudgns/Festival/venv/lib/python3.12/site-packages/requests/sessions.py", line 703, in send
    r = adapter.send(request, **kwargs)
        ^^^^^^^^^^^^^^^^^^^^^^^^^^^^^^^
  File "/home/skdudgns/Festival/venv/lib/python3.12/site-packages/requests/adapters.py", line 688, in send
    raise ConnectTimeout(e, request=request)
requests.exceptions.ConnectTimeout: HTTPConnectionPool(host='10.1.1.4', port=5000): Max retries exceeded with url: /chat (Caused by ConnectTimeoutError(<urllib3.connection.HTTPConnection object at 0x71c9617d1a30>, 'Connection to 10.1.1.4 timed out. (connect timeout=None)'))

2024-11-15 09:47:42 [ERROR] django.request (log): Internal Server Error: /api/chat_with_bot/
2024-11-15 09:48:59 [DEBUG] urllib3.connectionpool (connectionpool): Starting new HTTP connection (1): 10.1.1.4:5000
2024-11-15 09:51:11 [DEBUG] urllib3.connectionpool (connectionpool): Starting new HTTP connection (1): 10.1.1.4:5000
2024-11-15 09:51:15 [ERROR] api.views (views): ChatWithBotView: Error communicating with chatbot API.
URL: http://10.1.1.4:5000/chat
User Input: 축제 알려줘
Exception: HTTPConnectionPool(host='10.1.1.4', port=5000): Max retries exceeded with url: /chat (Caused by ConnectTimeoutError(<urllib3.connection.HTTPConnection object at 0x71c961640590>, 'Connection to 10.1.1.4 timed out. (connect timeout=None)'))
Traceback: Traceback (most recent call last):
  File "/home/skdudgns/Festival/venv/lib/python3.12/site-packages/urllib3/connection.py", line 199, in _new_conn
    sock = connection.create_connection(
           ^^^^^^^^^^^^^^^^^^^^^^^^^^^^^
  File "/home/skdudgns/Festival/venv/lib/python3.12/site-packages/urllib3/util/connection.py", line 85, in create_connection
    raise err
  File "/home/skdudgns/Festival/venv/lib/python3.12/site-packages/urllib3/util/connection.py", line 73, in create_connection
    sock.connect(sa)
TimeoutError: [Errno 110] Connection timed out

The above exception was the direct cause of the following exception:

Traceback (most recent call last):
  File "/home/skdudgns/Festival/venv/lib/python3.12/site-packages/urllib3/connectionpool.py", line 789, in urlopen
    response = self._make_request(
               ^^^^^^^^^^^^^^^^^^^
  File "/home/skdudgns/Festival/venv/lib/python3.12/site-packages/urllib3/connectionpool.py", line 495, in _make_request
    conn.request(
  File "/home/skdudgns/Festival/venv/lib/python3.12/site-packages/urllib3/connection.py", line 441, in request
    self.endheaders()
  File "/usr/lib/python3.12/http/client.py", line 1331, in endheaders
    self._send_output(message_body, encode_chunked=encode_chunked)
  File "/usr/lib/python3.12/http/client.py", line 1091, in _send_output
    self.send(msg)
  File "/usr/lib/python3.12/http/client.py", line 1035, in send
    self.connect()
  File "/home/skdudgns/Festival/venv/lib/python3.12/site-packages/urllib3/connection.py", line 279, in connect
    self.sock = self._new_conn()
                ^^^^^^^^^^^^^^^^
  File "/home/skdudgns/Festival/venv/lib/python3.12/site-packages/urllib3/connection.py", line 208, in _new_conn
    raise ConnectTimeoutError(
urllib3.exceptions.ConnectTimeoutError: (<urllib3.connection.HTTPConnection object at 0x71c961640590>, 'Connection to 10.1.1.4 timed out. (connect timeout=None)')

The above exception was the direct cause of the following exception:

Traceback (most recent call last):
  File "/home/skdudgns/Festival/venv/lib/python3.12/site-packages/requests/adapters.py", line 667, in send
    resp = conn.urlopen(
           ^^^^^^^^^^^^^
  File "/home/skdudgns/Festival/venv/lib/python3.12/site-packages/urllib3/connectionpool.py", line 843, in urlopen
    retries = retries.increment(
              ^^^^^^^^^^^^^^^^^^
  File "/home/skdudgns/Festival/venv/lib/python3.12/site-packages/urllib3/util/retry.py", line 519, in increment
    raise MaxRetryError(_pool, url, reason) from reason  # type: ignore[arg-type]
    ^^^^^^^^^^^^^^^^^^^^^^^^^^^^^^^^^^^^^^^^^^^^^^^^^^^
urllib3.exceptions.MaxRetryError: HTTPConnectionPool(host='10.1.1.4', port=5000): Max retries exceeded with url: /chat (Caused by ConnectTimeoutError(<urllib3.connection.HTTPConnection object at 0x71c961640590>, 'Connection to 10.1.1.4 timed out. (connect timeout=None)'))

During handling of the above exception, another exception occurred:

Traceback (most recent call last):
  File "/home/skdudgns/Festival/backend/api/views.py", line 249, in post
    response = requests.post(url, json={"input_user": user_input})
               ^^^^^^^^^^^^^^^^^^^^^^^^^^^^^^^^^^^^^^^^^^^^^^^^^^^
  File "/home/skdudgns/Festival/venv/lib/python3.12/site-packages/requests/api.py", line 115, in post
    return request("post", url, data=data, json=json, **kwargs)
           ^^^^^^^^^^^^^^^^^^^^^^^^^^^^^^^^^^^^^^^^^^^^^^^^^^^^
  File "/home/skdudgns/Festival/venv/lib/python3.12/site-packages/requests/api.py", line 59, in request
    return session.request(method=method, url=url, **kwargs)
           ^^^^^^^^^^^^^^^^^^^^^^^^^^^^^^^^^^^^^^^^^^^^^^^^^
  File "/home/skdudgns/Festival/venv/lib/python3.12/site-packages/requests/sessions.py", line 589, in request
    resp = self.send(prep, **send_kwargs)
           ^^^^^^^^^^^^^^^^^^^^^^^^^^^^^^
  File "/home/skdudgns/Festival/venv/lib/python3.12/site-packages/requests/sessions.py", line 703, in send
    r = adapter.send(request, **kwargs)
        ^^^^^^^^^^^^^^^^^^^^^^^^^^^^^^^
  File "/home/skdudgns/Festival/venv/lib/python3.12/site-packages/requests/adapters.py", line 688, in send
    raise ConnectTimeout(e, request=request)
requests.exceptions.ConnectTimeout: HTTPConnectionPool(host='10.1.1.4', port=5000): Max retries exceeded with url: /chat (Caused by ConnectTimeoutError(<urllib3.connection.HTTPConnection object at 0x71c961640590>, 'Connection to 10.1.1.4 timed out. (connect timeout=None)'))

2024-11-15 09:51:15 [ERROR] django.request (log): Internal Server Error: /api/chat_with_bot/
2024-11-15 09:53:26 [ERROR] api.views (views): ChatWithBotView: Error communicating with chatbot API.
URL: http://10.1.1.4:5000/chat
User Input: gsrdfg
Exception: HTTPConnectionPool(host='10.1.1.4', port=5000): Max retries exceeded with url: /chat (Caused by ConnectTimeoutError(<urllib3.connection.HTTPConnection object at 0x71c961643050>, 'Connection to 10.1.1.4 timed out. (connect timeout=None)'))
Traceback: Traceback (most recent call last):
  File "/home/skdudgns/Festival/venv/lib/python3.12/site-packages/urllib3/connection.py", line 199, in _new_conn
    sock = connection.create_connection(
           ^^^^^^^^^^^^^^^^^^^^^^^^^^^^^
  File "/home/skdudgns/Festival/venv/lib/python3.12/site-packages/urllib3/util/connection.py", line 85, in create_connection
    raise err
  File "/home/skdudgns/Festival/venv/lib/python3.12/site-packages/urllib3/util/connection.py", line 73, in create_connection
    sock.connect(sa)
TimeoutError: [Errno 110] Connection timed out

The above exception was the direct cause of the following exception:

Traceback (most recent call last):
  File "/home/skdudgns/Festival/venv/lib/python3.12/site-packages/urllib3/connectionpool.py", line 789, in urlopen
    response = self._make_request(
               ^^^^^^^^^^^^^^^^^^^
  File "/home/skdudgns/Festival/venv/lib/python3.12/site-packages/urllib3/connectionpool.py", line 495, in _make_request
    conn.request(
  File "/home/skdudgns/Festival/venv/lib/python3.12/site-packages/urllib3/connection.py", line 441, in request
    self.endheaders()
  File "/usr/lib/python3.12/http/client.py", line 1331, in endheaders
    self._send_output(message_body, encode_chunked=encode_chunked)
  File "/usr/lib/python3.12/http/client.py", line 1091, in _send_output
    self.send(msg)
  File "/usr/lib/python3.12/http/client.py", line 1035, in send
    self.connect()
  File "/home/skdudgns/Festival/venv/lib/python3.12/site-packages/urllib3/connection.py", line 279, in connect
    self.sock = self._new_conn()
                ^^^^^^^^^^^^^^^^
  File "/home/skdudgns/Festival/venv/lib/python3.12/site-packages/urllib3/connection.py", line 208, in _new_conn
    raise ConnectTimeoutError(
urllib3.exceptions.ConnectTimeoutError: (<urllib3.connection.HTTPConnection object at 0x71c961643050>, 'Connection to 10.1.1.4 timed out. (connect timeout=None)')

The above exception was the direct cause of the following exception:

Traceback (most recent call last):
  File "/home/skdudgns/Festival/venv/lib/python3.12/site-packages/requests/adapters.py", line 667, in send
    resp = conn.urlopen(
           ^^^^^^^^^^^^^
  File "/home/skdudgns/Festival/venv/lib/python3.12/site-packages/urllib3/connectionpool.py", line 843, in urlopen
    retries = retries.increment(
              ^^^^^^^^^^^^^^^^^^
  File "/home/skdudgns/Festival/venv/lib/python3.12/site-packages/urllib3/util/retry.py", line 519, in increment
    raise MaxRetryError(_pool, url, reason) from reason  # type: ignore[arg-type]
    ^^^^^^^^^^^^^^^^^^^^^^^^^^^^^^^^^^^^^^^^^^^^^^^^^^^
urllib3.exceptions.MaxRetryError: HTTPConnectionPool(host='10.1.1.4', port=5000): Max retries exceeded with url: /chat (Caused by ConnectTimeoutError(<urllib3.connection.HTTPConnection object at 0x71c961643050>, 'Connection to 10.1.1.4 timed out. (connect timeout=None)'))

During handling of the above exception, another exception occurred:

Traceback (most recent call last):
  File "/home/skdudgns/Festival/backend/api/views.py", line 249, in post
    response = requests.post(url, json={"input_user": user_input})
               ^^^^^^^^^^^^^^^^^^^^^^^^^^^^^^^^^^^^^^^^^^^^^^^^^^^
  File "/home/skdudgns/Festival/venv/lib/python3.12/site-packages/requests/api.py", line 115, in post
    return request("post", url, data=data, json=json, **kwargs)
           ^^^^^^^^^^^^^^^^^^^^^^^^^^^^^^^^^^^^^^^^^^^^^^^^^^^^
  File "/home/skdudgns/Festival/venv/lib/python3.12/site-packages/requests/api.py", line 59, in request
    return session.request(method=method, url=url, **kwargs)
           ^^^^^^^^^^^^^^^^^^^^^^^^^^^^^^^^^^^^^^^^^^^^^^^^^
  File "/home/skdudgns/Festival/venv/lib/python3.12/site-packages/requests/sessions.py", line 589, in request
    resp = self.send(prep, **send_kwargs)
           ^^^^^^^^^^^^^^^^^^^^^^^^^^^^^^
  File "/home/skdudgns/Festival/venv/lib/python3.12/site-packages/requests/sessions.py", line 703, in send
    r = adapter.send(request, **kwargs)
        ^^^^^^^^^^^^^^^^^^^^^^^^^^^^^^^
  File "/home/skdudgns/Festival/venv/lib/python3.12/site-packages/requests/adapters.py", line 688, in send
    raise ConnectTimeout(e, request=request)
requests.exceptions.ConnectTimeout: HTTPConnectionPool(host='10.1.1.4', port=5000): Max retries exceeded with url: /chat (Caused by ConnectTimeoutError(<urllib3.connection.HTTPConnection object at 0x71c961643050>, 'Connection to 10.1.1.4 timed out. (connect timeout=None)'))

2024-11-15 09:53:26 [ERROR] django.request (log): Internal Server Error: /api/chat_with_bot/
2024-11-16 01:18:06 [INFO] django.utils.autoreload (autoreload): Watching for file changes with StatReloader
2024-11-16 01:18:10 [WARNING] django.request (log): Not Found: /
2024-11-16 01:18:10 [WARNING] django.request (log): Not Found: /favicon.ico
2024-11-16 01:18:12 [WARNING] django.request (log): Not Found: /
2024-11-16 01:18:25 [WARNING] django.request (log): Not Found: /api/
2024-11-16 01:18:39 [WARNING] django.request (log): Method Not Allowed: /api/chat_with_bot/
